Workbook

Sheet 00_Overview
B2: 엔젤로보틱스㈜ (KOSDAQ 455900)
B3: 사모 CB·CPS 발행 검토 — 리서치 자료 집계
B5: 기준일 2026.08.25 / 재무수치 기준일 2026.06.30 (제10기 반기)
B7: 1. 한눈에 보기
B8: 구분 | C8: 내용 | D8: 구분 | E8: 내용
B9: 설립 / 상장 | C9: 2017.02 / 2024.03.26 (기술특례) | D9: 대표이사 | E9: 조남민 (2024.10)
B10: 발행주식총수 | C10: 15,392,981주 | D10: 이사회 의장·CTO | E10: 공경철 (창업자)
B11: 최대주주등 | C11: 공경철 외 2인 27.48% | D11: 2대주주 | E11: LG전자 6.24%
B12: 2025년 매출 | C12: 4,641백만원 | D12: 2026년 반기 매출 | E12: 1,295백만원 (-49.4% YoY)
B13: 2025년 영업손실 | C13: (10,276)백만원 | D13: 2026년 반기 영업손실 | E13: (6,163)백만원
B14: 자기자본 (26.6말) | C14: 30,982백만원 | D14: 즉시 가용 유동성 | E14: 25,063백만원
B15: 차입금 | C15: 없음 | D15: 미상환 CB·BW | E15: 없음
B16: 국내 시장점유율 | C16: 56% (2023년, 2위 21%) | D16: 해외 인허가 | E16: 태국·베트남·말레이시아
B19: 2. 시트 구성
B20: 시트 | C20: 내용 | D20: 주요 출처 | E20: 비고
B21: 01_회사개요·연혁 | C21: 기업 기본정보, 연혁 28건 | D21: 반기보고서
B22: 02_주주·경영진 | C22: 주주현황, 임원 8인, 스톡옵션 | D22: 반기보고서
B23: 03_손익계산서 | C23: 2020~2026 반기 손익 추이 | D23: 반기·사업보고서, 증권사 | E23: 가로형
B24: 04_재무상태표 | C24: 2020~2026 반기 재무상태 추이 | D24: 반기·사업보고서, 증권사 | E24: 가로형
B25: 05_재무비율 | C25: 안정성·수익성·성장성 지표 | D25: 산출 | E25: 가로형
B26: 06_제품별매출 | C26: 브랜드별·내수수출별 매출 | D26: 반기보고서 | E26: 가로형
B27: 07_추정치대비실적 | C27: 증권신고서 예측 대비 실적 | D27: 반기보고서
B28: 08_R&D·국가과제 | C28: 연구개발비, 국고보조금, 과제 3건 | D28: 반기보고서, SK증권 | E28: 가로형
B29: 09_인허가·수상 | C29: 해외 인허가, 기술 검증 이력 | D29: 반기보고서
B30: 10_시장·산업 | C30: 시장규모, 점유율, 침투율, 판매처 | D30: 증권사, 웹 | E30: 가로형
B31: 11_주가·밸류에이션 | C31: 월별 주가, 공모가 산정, Peer | D31: 반기보고서, 유진투자증권 | E31: 가로형
B32: 12_관리종목·시뮬레이션 | C32: 지정유예 현황, 자기자본 시뮬레이션 | D32: 반기보고서, 산출 | E32: 가로형
B33: 13_출처목록 | C33: 자료 8건 + 웹 소스 URL | D33: -
B36: 3. 범례
B37: 파란색 숫자 = 원자료 (공시·리포트에서 그대로 인용)
B38: 검은색 숫자 = 계산식 (합계·비율·증감률 등 수식으로 산출)
B39: 별도 표기가 없는 한 금액 단위는 백만원, K-IFRS 별도 기준 (종속회사 없음)
B40: ⚠️ 시장규모는 조사기관별 편차가 크므로 기준기관 미확정 상태임 (10_시장·산업 참조)
B42: 미확보 항목: 딜 조건 · CPS 자본분류 감사인 의견 · 아세안 수주 파이프라인 · BEP 매출 (발행사 확보 필요)
B44: ※ 수식이 포함된 시트가 있습니다. Excel에서 파일을 열면 자동으로 재계산됩니다.
B45: (작성 환경에 LibreOffice Calc가 없어 캐시값 없이 저장되었으므로, Excel 외 미리보기 도구에서는 수식 셀이 비어 보일 수 있습니다)

Sheet 01_회사개요·연혁
A2: 회사 개요 및 연혁
A3: 출처: 제10기 반기보고서(2026.08.14)
B5: 구분 | C5: 내용 | D5: 구분 | E5: 내용
B6: 회사명 | C6: 엔젤로보틱스 주식회사 | D6: 종목코드 | E6: 455900 (코스닥)
B7: 설립일 | C7: 2017년 2월 (구 ㈜에스지로보틱스) | D7: 상장일 | E7: 2024년 3월 26일
B8: 상장방식 | C8: 기술성장기업 특례상장 | D8: 인수인 | E8: NH투자증권
B9: 대표이사 | C9: 조남민 (2024.10 선임) | D9: 이사회 의장/CTO | E9: 공경철 (창업자)
B10: 자본금 | C10: 7,696,490,500원 | D10: 액면가 | E10: 500원
B11: 발행주식총수 | C11: 15,392,981주 | D11: 발행할 주식의 총수 | E11: 100,000,000주
B12: 본점 | C12: 서울 광진구 광나루로56길 85 테크노마트21 | D12: 감사인 | E12: 신한회계법인
B13: 사업장 | C13: 플래닛하남(생산, 24.04) / 플래닛대전(연구, 24.07) | D13: 종속회사 | E13: 없음 (별도 기준)
B14: 주요사업 | C14: 지능형 웨어러블 로봇 개발·제조·판매 및 국가연구개발 용역
B17: 주요 연혁
B18: 시기 | C18: 내용 | D18: 구분
B19: 2017.02 | C19: ㈜에스지로보틱스 설립 | D19: 회사설립
B20: 2017.05 | C20: LG전자 보통주 투자 유치 | D20: 투자유치
B21: 2018.02 | C21: 워크온슈트 평창 패럴림픽 성화봉송 지원 | D21: 경영활동
B22: 2018.09 | C22: ㈜엔젤로보틱스 사명 변경 | D22: 사명변경
B23: 2019.09 | C23: 의료기기 GMP 적합인정 획득 | D23: 인증
B24: 2020.01 | C24: Series A 97억원 투자 유치 | D24: 투자유치
B25: 2020.09 | C25: 엔젤렉스 M10 세브란스 재활병원 납품 | D25: 경영활동
B26: 2020.11 | C26: 제2회 사이배슬론 전동형 외골격 금메달·동메달 | D26: 수상
B27: 2021.07 | C27: Series B 180억원 투자 유치 | D27: 투자유치
B28: 2021.08 | C28: 엔젤렉스 M20 9개 병원 납품 | D28: 경영활동
B29: 2022.05 | C29: 말레이시아 UiTM 의과대학 전략적 협약(MOA) | D29: 협약체결
... B48: 2026.06 | C48: 범부처 '브레인 투 로봇' 개발 과제 주관기관 선정 | D48: 국가과제

Sheet 02_주주·경영진
A2: 주주 현황 및 경영진
A3: 기준일 2026.06.30 / 출처: 제10기 반기보고서
B5: 최대주주 및 특수관계인
B6: 성명 | C6: 관계 | D6: 주식수(주) | E6: 지분율
B7: 공경철 | C7: 본인 (이사회 의장/CTO) | D7: 3467560 | E7: 0.2256
B8: 나동욱 | C8: 임원 (임상총괄) | D8: 475680 | E8: 0.0309
B9: 정성훈 | C9: 기타 (공동목적보유확약) | D9: 281600 | E9: 0.0183
B10: 합계 | C10: - | D10: =SUM(D7:D9) | E10: =SUM(E7:E9)
B12: 주식 소유현황
B13: 구분 | C13: 주주명 | D13: 주식수(주) | E13: 지분율
B14: 5% 이상 주주 | C14: 공경철 | D14: 3467560 | E14: 0.2256
B15: 5% 이상 주주 | C15: LG전자 주식회사 | D15: 960000 | E15: 0.0624
B16: 우리사주조합 | C16: 우리사주조합 | D16: 119719 | E16: 0.0078
B17: 소액주주 | C17: 69,348명 | D17: 8730773 | E17: 0.568
B18: 발행주식총수 | C18: - | D18: 15392981 | E18: 1
A20: 주1) 최대주주 등은 코스닥 상장규정상 의무보유 1년을 거래소 협의를 통해 3년으로 자발 연장 (미행사 주식매수선택권은 1년 6개월)
A21: 주2) 설립 이후 최대주주 변동 없음 / 서강대학교산학협력단 2.28%, 연세대학교의료원산학협력단 0.29% 보유 (상장 시점 기준, 출처: 유진투자증권)
B24: 주요 경영진
B25: 성명 | C25: 직위 | D25: 선임 | E25: 구분 | F25: 주요 경력
B26: 조남민 | C26: 대표이사 (CEO) | D26: 2024.10 | E26: 사내이사 | F26: Medtronic Sr. Sales executive, ZimmerBiomet APAC Business Manager, Philips Korea GM, Trackman Greater Asia CEO
B27: 공경철 | C27: 이사회 의장/CTO | D27: 2017.02 | E27: 사내이사 | F27: UC Berkeley 기계공학 박사, 서강대 부교수, KAIST 기계공학과 교수
B28: 나동욱 | C28: 이사 (임상총괄) | D28: 2017.02 | E28: 미등기 | F28: 연세대 의대 재활의학 교수, 융합의학과 겸임교수
B29: 이수찬 | C29: 이사 (마케팅총괄) | D29: 2024.09 | E29: 미등기 | F29: 삼성전자, 현대오일뱅크, LG전자, 디케이메디칼시스템
B30: 황상탁 | C30: 이사 (인사총괄) | D30: 2025.11 | E30: 미등기 | F30: LG Display, SK Telecom, NCSOFT, 한국아스텔라스 이사
B31: 김주민 | C31: 이사 (영업총괄) | D31: 2026.02 | E31: 미등기 | F31: 한국존슨앤존슨메디칼, 메드트로닉코리아 이사 (22년)
B32: 장호식 | C32: 이사 (품질총괄) | D32: 2026.03 | E32: 미등기 | F32: 지멘스 헬시니어스 이사, 고영테크놀러지 상무
B33: 정동선 | C33: 이사 (재무총괄) | D33: 2026.04 | E33: 미등기 | F33: 한영회계법인 Manager, 이지홀딩스, 한울회계법인 회계사
B34: 김문성 | C34: 독립이사 | D34: 2022.05 | E34: 독립이사 | F34: 의정부지방법원 부장판사, 법무법인 이제 변호사
B35: 김미현 | C35: 독립이사 | D35: 2024.10 | E35: 독립이사 | F35: 사법시험·행정고시 합격, 법무법인(유한)광장
B36: 김인숙 | C36: 감사 | D36: 2024.03 | E36: 감사 | F36: 삼일회계법인 공인회계사, 검사, KB증권 사외이사
B39: 미행사 주식매수선택권
B40: 회차 | C40: 잔여수량(주) | D40: 행사가격(원) | E40: 행사가능 개시 | F40: 현 주가 대비
B41: 8회차 | C41: 125000 | D41: 8188 | E41: 2024.11.16 | F41: 내가격
B42: 9회차 | C42: 13500 | D42: 8188 | E42: 2025.06.01 | F42: 내가격
B43: 10회차 | C43: 22400 | D43: 8190 | E43: 2026.04.01 | F43: 내가격
B44: 11회차 | C44: 500000 | D44: 27069 | E44: 2027.10.17 | F44: 외가격
B45: 12회차 | C45: 253000 | D45: 28432 | E45: 2029.04.01 | F45: 외가격
B46: 합계 | C46: =SUM(C41:C45) | D46: - | E46: - | F46: =C46/15392981
A47: 주) 현 주가 대비 판정은 2026년 6월 평균 23,332원 기준

Sheet 03_손익계산서
A2: 손익계산서 추이 (K-IFRS 별도)
A3: 단위: 백만원 / 출처: 제10기 반기보고서, 제9기 사업보고서, SK증권·리딩투자증권
B5: 구분 | C5: 2020 | D5: 2021 | E5: 2022 | F5: 2023 | G5: 2024 | H5: 2025 | I5: 2025 반기 | J5: 2026 반기
B6: 매출액 | C6: 209 | D6: 814 | E6: 2184 | F6: 5146 | G6: 4211 | H6: 4641 | I6: 2562 | J6: 1295
B7: 매출원가 | C7: 128 | D7: 564 | E7: 1182 | F7: 2379 | G7: 1702 | H7: 2030 | I7: 932 | J7: 512
B8: 매출총이익 | C8: =C6-C7 | D8: =D6-D7 | E8: =E6-E7 | F8: =F6-F7 | G8: =G6-G7 | H8: =H6-H7 | I8: =I6-I7 | J8: =J6-J7
B9: 매출총이익률 | C9: =IFERROR(C8/C6,"") | D9: =IFERROR(D8/D6,"") | E9: =IFERROR(E8/E6,"") | F9: =IFERROR(F8/F6,"") | G9: =IFERROR(G8/G6,"") | H9: =IFERROR(H8/H6,"") | I9: =IFERROR(I8/I6,"") | J9: =IFERROR(J8/J6,"")
B10: 판매비와관리비 | C10: =C8-C11 | D10: =D8-D11 | E10: =E8-E11 | F10: =F8-F11 | G10: 13351 | H10: 12888 | I10: 6296 | J10: 6946
B11: 영업이익(손실) | C11: -2471 | D11: -4829 | E11: -7101 | F11: -6497 | G11: -10842 | H11: -10276 | I11: -4666 | J11: -6163
B12: 영업이익률 | C12: =IFERROR(C11/C6,"") | D12: =IFERROR(D11/D6,"") | E12: =IFERROR(E11/E6,"") | F12: =IFERROR(F11/F6,"") | G12: =IFERROR(G11/G6,"") | H12: =IFERROR(H11/H6,"") | I12: =IFERROR(I11/I6,"") | J12: =IFERROR(J11/J6,"")
B13: 금융수익 | G13: 1041 | H13: 851 | I13: 481 | J13: 2578
B14: 금융비용 | G14: 77 | H14: 129 | I14: 61 | J14: 65
B15: 법인세비용차감전순손실 | C15: -2472 | D15: -24094 | E15: -6797 | F15: -9239 | G15: -10006 | H15: -9715 | I15: -4405 | J15: -3665
B16: 당기순손실 | C16: -2472 | D16: -24094 | E16: -6797 | F16: -9239 | G16: -10006 | H16: -9715 | I16: -4405 | J16: -3665
B17: 주당순손실(원) | C17: -371 | D17: -3201 | E17: -770 | F17: -913 | G17: -687 | H17: -642 | I17: -292 | J17: -240
A19: 주1) 2020~2023년 매출원가는 SK증권 보고서의 매출총이익을 역산한 값이며, 판매비와관리비는 매출총이익에서 영업이익을 차감한 계산값임
A20: 주2) 2024·2025년 및 2026년 반기는 제9기 사업보고서·제10기 반기보고서 확정치, 2020~2023년은 증권사 보고서 기준
A21: 주3) 2026년 반기 매출액은 전년 동기 2,562백만원 대비 49.4% 감소
A22: 주4) 2024년 이후 판매비와관리비는 공시 확정치를 그대로 입력하였음. 2020~2023년만 '매출총이익 - 영업이익'으로 산출한 계산값임

Sheet 04_재무상태표
A2: 재무상태표 추이 (K-IFRS 별도)
A3: 단위: 백만원 / 출처: 제10기 반기보고서 「요약 별도 재무정보」, 리딩투자증권
B5: 구분 | C5: 2020 | D5: 2021 | E5: 2022 | F5: 2023 | G5: 2024 | H5: 2025 | I5: 2026 반기
B6: 유동자산 | C6: 5500 | D6: 18100 | E6: 12500 | F6: 17200 | G6: 34310 | H6: 28624 | I6: 28922
B7: 현금및현금성자산 | C7: 5200 | D7: 3100 | E7: 2100 | F7: 4200 | G7: 15064 | H7: 3151 | I7: 5053
B8: 단기금융상품 | C8: 0 | D8: 14000 | E8: 8200 | F8: 10400 | G8: 16000 | H8: 22000 | I8: 20010
B9: 매출채권 | C9: 0 | D9: 200 | E9: 400 | F9: 1000 | G9: 722 | H9: 723 | I9: 457
B10: 재고자산 | C10: 200 | D10: 500 | E10: 1200 | F10: 900 | G10: 1085 | H10: 1340 | I10: 1308
B11: 비유동자산 | C11: 1000 | D11: 4100 | E11: 4000 | F11: 4100 | G11: 9567 | H11: 8409 | I11: 7344
B12: 유형자산 | C12: 500 | D12: 3400 | E12: 3300 | F12: 3100 | G12: 3511 | H12: 4070 | I12: 4023
B13: 무형자산 | C13: 200 | D13: 200 | E13: 300 | F13: 700 | G13: 1031 | H13: 870 | I13: 793
B14: 자산총계 | C14: =C6+C11 | D14: =D6+D11 | E14: =E6+E11 | F14: =F6+F11 | G14: =G6+G11 | H14: =H6+H11 | I14: =I6+I11
B15: 유동부채 | C15: 100 | D15: 34600 | E15: 34700 | F15: 11000 | G15: 1135 | H15: 1222 | I15: 1892
B16: 비유동부채 | C16: 300 | D16: 1500 | E16: 1500 | F16: 1600 | G16: 2413 | H16: 3186 | I16: 3392
B17: 부채총계 | C17: =C15+C16 | D17: =D15+D16 | E17: =E15+E16 | F17: =F15+F16 | G17: =G15+G16 | H17: =H15+H16 | I17: =I15+I16
B18: 자본금 | G18: 7496 | H18: 7609 | I18: 7696
B19: 자본잉여금 | G19: 90007 | H19: 91979 | I19: 94049
B20: 결손금 | G20: -59467 | H20: -69098 | I20: -72763
B21: 자본총계 | C21: =C14-C17 | D21: =D14-D17 | E21: =E14-E17 | F21: =F14-F17 | G21: =G14-G17 | H21: =H14-H17 | I21: =I14-I17
B23: 즉시 가용 유동성 (현금+단기금융상품) | C23: =C7+C8 | D23: =D7+D8 | E23: =E7+E8 | F23: =F7+F8 | G23: =G7+G8 | H23: =H7+H8 | I23: =I7+I8
B24: 금융기관 차입금 | C24: - | D24: - | E24: - | F24: - | G24: - | H24: - | I24: -
A26: 주1) 2024·2025년 및 2026년 반기는 제10기 반기보고서 「요약 별도 재무정보」 확정치
A27: 주2) 2020~2023년은 리딩투자증권 보고서의 억원 단위 표기를 백만원으로 환산한 근사치이므로 소수점 이하 정밀도가 낮음
A28: 주3) 2021~2022년 자본총계가 음(-)인 것은 상장 전 발행한 상환전환우선주(RCPS)가 부채로 계상되었기 때문이며, 2023년 보통주 전환으로 해소됨
A29: 주4) 2026년 반기말 기준 금융기관 차입금·회사채·기업어음·단기사채 미상환 잔액이 모두 없음 (반기보고서 「채무증권 발행실적」)

Sheet 05_재무비율
A2: 주요 재무비율
A3: 출처: 03_손익계산서·04_재무상태표 기준 산출
B5: 구분 | C5: 2020 | D5: 2021 | E5: 2022 | F5: 2023 | G5: 2024 | H5: 2025 | I5: 2026 반기
B6: 부채비율 | C6: =IFERROR('04_재무상태표'!C17/'04_재무상태표'!C21,"") | D6: =IFERROR('04_재무상태표'!D17/'04_재무상태표'!D21,"") | E6: =IFERROR('04_재무상태표'!E17/'04_재무상태표'!E21,"") | F6: =IFERROR('04_재무상태표'!F17/'04_재무상태표'!F21,"") | G6: =IFERROR('04_재무상태표'!G17/'04_재무상태표'!G21,"") | H6: =IFERROR('04_재무상태표'!H17/'04_재무상태표'!H21,"") | I6: =IFERROR('04_재무상태표'!I17/'04_재무상태표'!I21,"")
B7: 유동비율 | C7: =IFERROR('04_재무상태표'!C6/'04_재무상태표'!C15,"") | D7: =IFERROR('04_재무상태표'!D6/'04_재무상태표'!D15,"") | E7: =IFERROR('04_재무상태표'!E6/'04_재무상태표'!E15,"") | F7: =IFERROR('04_재무상태표'!F6/'04_재무상태표'!F15,"") | G7: =IFERROR('04_재무상태표'!G6/'04_재무상태표'!G15,"") | H7: =IFERROR('04_재무상태표'!H6/'04_재무상태표'!H15,"") | I7: =IFERROR('04_재무상태표'!I6/'04_재무상태표'!I15,"")
B8: 자기자본비율 | C8: =IFERROR('04_재무상태표'!C21/'04_재무상태표'!C14,"") | D8: =IFERROR('04_재무상태표'!D21/'04_재무상태표'!D14,"") | E8: =IFERROR('04_재무상태표'!E21/'04_재무상태표'!E14,"") | F8: =IFERROR('04_재무상태표'!F21/'04_재무상태표'!F14,"") | G8: =IFERROR('04_재무상태표'!G21/'04_재무상태표'!G14,"") | H8: =IFERROR('04_재무상태표'!H21/'04_재무상태표'!H14,"") | I8: =IFERROR('04_재무상태표'!I21/'04_재무상태표'!I14,"")
B9: 매출총이익률 | C9: =IFERROR('03_손익계산서'!C8/'03_손익계산서'!C6,"") | D9: =IFERROR('03_손익계산서'!D8/'03_손익계산서'!D6,"") | E9: =IFERROR('03_손익계산서'!E8/'03_손익계산서'!E6,"") | F9: =IFERROR('03_손익계산서'!F8/'03_손익계산서'!F6,"") | G9: =IFERROR('03_손익계산서'!G8/'03_손익계산서'!G6,"") | H9: =IFERROR('03_손익계산서'!H8/'03_손익계산서'!H6,"") | I9: =IFERROR('03_손익계산서'!J8/'03_손익계산서'!J6,"")
B10: 영업이익률 | C10: =IFERROR('03_손익계산서'!C11/'03_손익계산서'!C6,"") | D10: =IFERROR('03_손익계산서'!D11/'03_손익계산서'!D6,"") | E10: =IFERROR('03_손익계산서'!E11/'03_손익계산서'!E6,"") | F10: =IFERROR('03_손익계산서'!F11/'03_손익계산서'!F6,"") | G10: =IFERROR('03_손익계산서'!G11/'03_손익계산서'!G6,"") | H10: =IFERROR('03_손익계산서'!H11/'03_손익계산서'!H6,"") | I10: =IFERROR('03_손익계산서'!J11/'03_손익계산서'!J6,"")
B11: 세전손실 / 자기자본 | C11: =IFERROR('03_손익계산서'!C15/'04_재무상태표'!C21,"") | D11: =IFERROR('03_손익계산서'!D15/'04_재무상태표'!D21,"") | E11: =IFERROR('03_손익계산서'!E15/'04_재무상태표'!E21,"") | F11: =IFERROR('03_손익계산서'!F15/'04_재무상태표'!F21,"") | G11: =IFERROR('03_손익계산서'!G15/'04_재무상태표'!G21,"") | H11: =IFERROR('03_손익계산서'!H15/'04_재무상태표'!H21,"") | I11: =IFERROR('03_손익계산서'!J15/'04_재무상태표'!I21,"")
A13: 주1) 마지막 열은 2026년 반기 손익을 2026년 반기말 재무상태와 대응시킨 것으로, 연간 환산치가 아님
A14: 주2) 세전손실/자기자본 비율은 코스닥 관리종목 계속사업손실 요건의 판정 지표임 (12_관리종목·시뮬레이션 참조)
A15: 주3) 2020~2023년은 근사 환산치 기반이므로 참고용

Sheet 06_제품별매출
A2: 제품별 매출 실적
A3: 단위: 백만원 / 출처: 제10기 반기보고서 「매출 실적」
B5: 매출유형 | C5: 품목 | D5: 2024 | E5: 2025 | F5: 2026 반기 | G5: 2025 비중 | H5: 2026반기 비중
B6: 제품매출 | C6: angel MEDI (내수) | D6: 3129 | E6: 1446 | F6: 650 | G6: =IFERROR(E6/E$13,"") | H6: =IFERROR(F6/F$13,"")
B7: 제품매출 | C7: angel MEDI (수출) | D7: 0 | E7: 241 | F7: 125 | G7: =IFERROR(E7/E$13,"") | H7: =IFERROR(F7/F$13,"")
B8: 제품매출 | C8: angel SUIT | D8: 369 | E8: 1380 | F8: 192 | G8: =IFERROR(E8/E$13,"") | H8: =IFERROR(F8/F$13,"")
B9: 제품매출 | C9: angel GEAR | D9: 248 | E9: 121 | F9: 30 | G9: =IFERROR(E9/E$13,"") | H9: =IFERROR(F9/F$13,"")
B10: 제품매출 | C10: angel KIT | D10: 26 | E10: 116 | F10: 0 | G10: =IFERROR(E10/E$13,"") | H10: =IFERROR(F10/F$13,"")
B11: 용역매출 | C11: 웨어러블로봇 개발용역 | D11: 419 | E11: 758 | F11: 44 | G11: =IFERROR(E11/E$13,"") | H11: =IFERROR(F11/F$13,"")
B12: 용역매출 | C12: 유상유지보수 | D12: 20 | E12: 579 | F12: 254 | G12: =IFERROR(E12/E$13,"") | H12: =IFERROR(F12/F$13,"")
B13: 합계 | C13: - | D13: =SUM(D6:D12) | E13: =SUM(E6:E12) | F13: =SUM(F6:F12) | G13: =IFERROR(E13/E13,"") | H13: =IFERROR(F13/F13,"")
B15: 수출 비중 | D15: =E7/E13 | E15: =F7/F13
A17: 주1) angel MEDI 내수 매출은 2024년 3,129백만원에서 2026년 반기 650백만원으로 축소
A18: 주2) angel SUIT는 2025년 전년 대비 3.7배, 유상유지보수는 29배 증가
A19: 주3) 수출은 2025년 최초 발생 (angel MEDI 241백만원)
B22: 판매처 구성 (2023년)
B23: 판매처 | C23: 비중 | D23: 판매처 | E23: 비중
B24: 회복기재활의료기관 | C24: 0.38 | D24: 재활병원 | E24: 0.1
B25: 상급종합병원 | C25: 0.21 | D25: 요양병원 | E25: 0.08
B26: 장애인복지관 | C26: 0.1 | D26: 대학교 | E26: 0.03
B27: 재활학교 | C27: 0.1 | D27: 합계 | E27: 1
A28: 출처: 엔젤로보틱스, 한국IR협의회 기업리서치센터(2024.09.26)

Sheet 07_추정치대비실적
A2: 증권신고서 추정치 대비 실적
A3: 단위: 백만원 / 출처: 제10기 반기보고서 「영업실적 등 예측치 대비 실적 비교」 (인수인: NH투자증권)
B5: 구분 | C5: 예측치 | D5: 실적치 | E5: 달성 여부 | F5: 괴리율
B6: 2024년 매출액 | C6: 9016 | D6: 4211 | E6: 미달성 | F6: 0.5329
B7: 2024년 영업이익 | C7: -5141 | D7: -10842 | E7: 미달성 | F7: 1.1089
B8: 2024년 당기순이익 | C8: -4407 | D8: -10006 | E8: 미달성 | F8: 1.2705
B9: 2025년 매출액 | C9: 20842 | D9: 4641 | E9: 미달성 | F9: 0.7773
B10: 2025년 영업이익 | C10: 1766 | D10: -10276 | E10: 미달성 | F10: 6.8188
B11: 2025년 당기순이익 | C11: 2364 | D11: -9715 | E11: 미달성 | F11: 5.1096
B12: 2026년 매출액 | C12: 36179 | E12: -
B13: 2026년 영업이익 | C13: 10643 | E13: -
B14: 2026년 당기순이익 | C14: 11450 | E14: -
B16: 2026년 반기 실적 (참고) | C16: - | D16: 매출 1,295 / 영업손실 (6,163) | E16: - | F16: -
A18: 주1) 괴리율 = (예측치 - 실적치) / 예측치
A19: 주2) 회사가 공시한 괴리 사유: ① 의정갈등 장기화에 따른 의료기관 투자 위축 ② 유럽 CE MDR 인증 지연에 따른 수출 발생 지연 ③ 정부 주도 산업안전 웨어러블 로봇 보급 예산 감소
A20: 주3) 2025년 매출 미달분 중 인증 지연 요인이 24%p를 차지하며, 해당 요인은 아세안 3개국 인허가 완결로 해소

Sheet 08_R&D·국가과제
A2: 연구개발비 및 국가연구개발과제
A3: 단위: 백만원 / 출처: 제10기 반기보고서 「연구개발비용」·「국가연구개발 수행현황」, SK증권
B5: 구분 | C5: 2022 | D5: 2023 | E5: 2024 | F5: 2025 | G5: 2026 반기
B6: 인건비 | E6: 2104 | F6: 2586 | G6: 1287
B7: 재료비·외주비 | E7: 1529 | F7: 1862 | G7: 808
B8: 연구개발비 합계 | C8: 3461 | D8: 3378 | E8: 3633 | F8: 4449 | G8: 2095
B9: 국고보조금 | C9: -1585 | D9: -2183 | E9: -1202 | F9: -1731 | G9: -766
B10: 보조금 차감 후 | C10: =C8+C9 | D10: =D8+D9 | E10: =E8+E9 | F10: =F8+F9 | G10: =G8+G9
B11: 보조금 분담률 | C11: =IFERROR(-C9/C8,"") | D11: =IFERROR(-D9/D8,"") | E11: =IFERROR(-E9/E8,"") | F11: =IFERROR(-F9/F8,"") | G11: =IFERROR(-G9/G8,"")
B12: 매출액 대비 R&D 비율 | C12: 1.58 | D12: 0.66 | E12: 0.8628 | F12: 0.9585 | G12: 1.6173
A14: 주1) 2022~2023년은 SK증권 보고서 기준, 2024년 이후는 반기보고서·사업보고서 확정치
A15: 주2) 국고보조금이 연구개발비의 33~39%를 실제로 차감하여 영업손실 규모를 축소시키는 구조
B18: 수행 중인 국가연구개발과제 (2026년 반기 기준)
B19: 과제명 | C19: 연구개발기간 | D19: 비고
B20: 운동-감각 동기화가 가능한 Brain-to-Robot 풀스택 시스템 개발 및 상용화 | C20: 2026.04~2032.12 | D20: 수행중 (주관기관)
B21: AI 기반의 웨어러블 로봇의 개인화 및 정밀건강 진단 서비스 개발 | C21: 2026.05~2027.04 | D21: 수행중
B22: 소방대원 활동성 등 수행능력 지원을 위한 외골격 로보틱 슈트 개발 | C22: 2026.04~2028.12 | D22: 수행중
B24: 과거 수행 과제 (2024년 사업보고서 기준, 참고)
B25: 웨어러블 로봇의 헬스케어 시장 확장을 위한 비즈니스 인프라 개발 | C25: 2025.01~2025.12
B26: 코어리스 마이크로모터 제조기술 개발 및 성능 검증 | C26: 2024.10~2028.12
B27: AI 기반 로봇을 위한 Sim-to-real 수준의 고토크-무저항 구동모듈 개발 | C27: 2024.07~2026.12
B28: 조선소 Yard 위보기 용접 보조용 스마트 웨어러블 슈트 제품화 | C28: 2024.07~2026.12
B29: 가정과 일상 헬스케어 시장을 위한 웨어러블 로봇 제품 및 서비스 플랫폼 개발 | C29: 2022.04~2025.12
B30: 착용형 보행보조로봇 기반 재택 보행 재활 서비스 모델 개발 및 실증 | C30: 2023.07~2025.12
A32: 출처: SK증권 기업분석(2025.05.29), 2024년 사업보고서 기준

Sheet 09_인허가·수상
A2: 해외 인허가 및 기술 검증 이력
A3: 출처: 제10기 반기보고서 연혁, 리딩투자증권(2025.12.16)
B5: 해외 인허가 현황
B6: 국가/지역 | C6: 규제기관 | D6: 대상 제품 | E6: 현황
B7: 태국 | C7: TFDA | D7: 엔젤렉스 M20 | E7: 2025.06 인증 획득
B8: 베트남 | C8: 보건복지부(MOH) | D8: 엔젤렉스 M20 / angel SUIT H10 | E8: 2025.07 인증 획득
B9: 말레이시아 | C9: 의료기기청(MDA) | D9: 엔젤렉스 M20 | E9: 2025.12 인증 → 2026.01 공식 출시
B10: 말레이시아 UiTM | C10: 의과대학 | D10: 임상 협력 | E10: 2022.05 전략적 협약(MOA)
B11: 인도네시아·싱가포르 | C11: 각국 규제기관 | D11: 엔젤렉스 M20 외 | E11: 진행 중
B12: 유럽 | C12: CE MDR | D12: 엔젤렉스 M20 외 | E12: 지연 중
B13: 미국 | C13: FDA | D13: angel GEAR (ANGEL X) | E13: 2022.12 등록 완료
B14: 미국 | C14: FDA | D14: 의료기기 라인 | E14: 단계적 추진
A15: 주) 말레이시아 의료기기 시장은 2027년까지 약 27억 달러 규모로 성장 전망 (리딩투자증권)
B18: 기술 검증 이력
B19: 시기 | C19: 구분 | D19: 내용
B20: 2018.02 | C20: 행사 | D20: 워크온슈트 평창 패럴림픽 성화봉송 지원
B21: 2018.12 | C21: 수상 | D21: 2018 올해의 대한민국 로봇기업
B22: 2020.11 | C22: 수상 | D22: 제2회 사이배슬론 전동형 외골격 금메달·동메달
B23: 2022.10 | C23: 선정 | D23: 국가연구개발 우수성과 100선 (과학기술정보통신부)
B24: 2023.02 | C24: 선정 | D24: 산업통상자원부 기계·장비·로봇 분야 R&D 우수성과
B25: 2023.12 | C25: 선정 | D25: 산업통상자원부 산업기술 대표 성과 10선 (워크온슈트)
B26: 2024.06 | C26: 수상 | D26: angel GEAR 독일 레드닷 디자인 어워드
B27: 2024.07 | C27: 논문 | D27: JAMA Network Open 게재 (뇌성마비 아동 90명 임상)
B28: 2024.10 | C28: 수상 | D28: 제3회 사이배슬론 전동형 외골격 금메달 (2연패)
B29: - | C29: 논문 | D29: Stroke (IF 8.9) 게재 (급성기 뇌졸중 160명 다기관 RCT)
B30: 2025.12 | C30: 수상 | D30: 범부처 의료기기 R&D 어워즈 한국연구재단 이사장상
B31: 2026.03 | C31: 선정 | D31: 파이낸셜타임즈 아시아태평양 고성장 기업 500
B33: 특허 출원 | C33: 75 | D33: 건
B34: 임상 케이스 논문 | C34: 10 | D34: 편
A35: 핵심특허: 보행 의도 파악(10-1317354) / 정밀 힘 제어(10-1477401) / 보행 주기별 제어(10-2162485)
A36: 출처: 한국IR협의회 기업리서치센터(2024.09.26), 제10기 반기보고서

Sheet 10_시장·산업
A2: 시장 규모 및 산업 구조
A3: ⚠️ 조사기관별 편차가 크므로 기준기관 미확정 상태
B5: 글로벌 시장 규모
B6: 구분 | C6: 기준연도 | D6: 규모 | E6: 전망연도 | F6: 규모 | G6: CAGR / 출처
B7: 의료용 로봇 | C7: 2022년 | D7: 116.6억 USD | E7: 2030년 | F7: 722.2억 USD | G7: +25.60% / GII
B8: 재활로봇 | C8: 2023년 | D8: 8.63억 USD | E8: 2028년 | F8: 46.40억 USD | G8: +39.98% / technavio
B9: 외골격 웨어러블 로봇 | C9: 2026년 | D9: 13.6억 USD | E9: 2034년 | F9: 69.5억 USD | G9: +27.3% / Fortune Business Insights
B10: 군용 로봇 | C10: 2026년 | D10: 216억 USD | E10: 2034년 | F10: 429억 USD | G10: +8.96% / 시장조사기관
A11: ⚠️ 재활로봇 CAGR은 기관별로 14.1%~46.6%까지 편차가 있어 본문 인용 시 기준기관 확정 필요
B14: 국내 시장
B15: 구분 | C15: 수치 | D15: 기준 | E15: 출처
B16: 국내 로봇산업 매출 | C16: 6조 1,695억원 | D16: 2024년 | E16: 한국로봇산업진흥원 로봇산업 실태조사 (정부승인통계)
B17: 국내 웨어러블 로봇 시장 CAGR | C17: 42.6% | D17: 2023~2030년 | E17: 엔젤로보틱스 IR Book / 유진투자증권
B18: 용도별 구성 (국내) | C18: 의료 42% / 산업 23% / 기타 35% | D18: - | E18: 리딩투자증권
B19: 용도별 구성 (해외) | C19: 의료 42% / 산업 22% / 기타 36% | D19: - | E19: 리딩투자증권
B22: 국내 재활 웨어러블 로봇 시장점유율 (2023년)
B23: 구분 | C23: 엔젤로보틱스 | D23: D사 | E23: F사 | F23: E사 | G23: 합계
B24: 시장점유율 | C24: 0.56 | D24: 0.21 | E24: 0.1 | F24: 0.07 | G24: =SUM(C24:F24)
A25: 출처: 엔젤로보틱스, 한국IR협의회 기업리서치센터 / ⚠️ 경쟁사 실명 미상, 2023년 기준
B28: 침투율 및 잠재 시장
B29: 구분 | C29: 수치 | D29: 의미 | E29: 출처
B30: 재활전문기관 보행재활로봇 보유율 | C30: 8% | D30: 시장 개화 초기 단계 | E30: 엔젤로보틱스 IR Book / 유진투자증권
B31: 수익시장 내 침투율 | C31: 2.5% | D31: 잔여 시장이 40배 규모 | E31: 엔젤로보틱스 IR Book / 유진투자증권
B32: 소아 뇌성마비 환자 수 | C32: 약 8만명 | D32: 수가 적응증 확대 시 개방 | E32: 엔젤로보틱스 IR Book / 유진투자증권
B33: 병원 구매비용 회수기간 | C33: 일반병원 1.3년 / 회복기재활병원 0.9년 | D33: 교체주기 5년 대비 조기 회수 | E33: 한국IR협의회
B36: 수가 체계 및 산업 구조
B37: 구분 | C37: 내용
B38: 급여화 시점 | C38: 2022년 2월 보행재활로봇 건강보험 급여화 적용
B39: 적용 대상 | C39: 발병 6개월 이내 뇌졸중 환자 (FAC 2등급 이하), 로봇정형운동장치 3등급 보행로봇에 한함
B40: 수가 코드 | C40: 로봇보행재활(MM304) / 보행치료(MM302) / 동작분석(EZ774)
B41: 산업 특성 | C41: 국산 재활로봇 다수가 신의료기술평가에서 '기존기술' 판정을 받아 별도 수가 미확보. 급여 미적용 시 환자 전액 부담으로 고가 장비 판매가 사실상 곤란
B42: 정책 방향 | C42: 보건복지부, 척수손상·파킨슨 등으로 수가 적응증 확대 추진
B43: 상반된 흐름 | C43: 산업안전 분야는 '스마트 안전장비 보급확산' 예산 감소로 B2G 시장 축소
B46: 국내외 경쟁사
B47: 구분 | C47: 기업 | D47: 설립/상장 | E47: 비고
B48: 국내 상장 | C48: 피앤에스로보틱스 (460940) | D48: 2003년 설립 / 2024.07 상장 | E48: 보행재활훈련 로봇 Walkbot (트레드밀 기반 고정형)
B49: 국내 비상장 | C49: FRT로보틱스 | D49: 2015년 | E49: 웨어러블 로봇
B50: 국내 비상장 | C50: 헥사휴먼케어 | D50: 2016년 | E50: 웨어러블 로봇
B51: 국내 비상장 | C51: 코스모로보틱스 | D51: 2016년 | E51: 웨어러블 로봇
B52: 해외 상장 | C52: 라이프워드 (구 리워크, 나스닥) | D52: 이스라엘 | E52: 2014.06 FDA 하지 외골격로봇 허가
...

Sheet 11_주가·밸류에이션
A2: 주가 추이 및 밸류에이션
A3: 출처: 제10기 반기보고서 「주가 및 주식거래실적」, 유진투자증권 IPO 분석(2024.03)
B5: 2026년 상반기 월별 주가 및 거래실적
B6: 구분 | C6: 2026.01 | D6: 2026.02 | E6: 2026.03 | F6: 2026.04 | G6: 2026.05 | H6: 2026.06
B7: 월별 최고가(원) | C7: 39500 | D7: 37200 | E7: 30800 | F7: 30350 | G7: 30200 | H7: 31600
B8: 월별 최저가(원) | C8: 28850 | D8: 33300 | E8: 24800 | F8: 25300 | G8: 25200 | H8: 18230
B9: 평균주가(원) | C9: 34398 | D9: 34947 | E9: 27479 | F9: 28032 | G9: 27992 | H9: 23332
B10: 월간 거래량(주) | C10: 14923873 | D10: 2611464 | E10: 1877342 | F10: 1338647 | G10: 1864844 | H10: 2861488
B12: 시가총액(백만원) | C12: =C9*15392981/1000000 | D12: =D9*15392981/1000000 | E12: =E9*15392981/1000000 | F12: =F9*15392981/1000000 | G12: =G9*15392981/1000000 | H12: =H9*15392981/1000000
A13: 주) 시가총액은 월 평균주가 × 발행주식총수 15,392,981주로 산출한 참고치
B16: 장기 주가 추이
B17: 시점 | C17: 주가(원) | D17: 비고
B18: 2024.03.26 (상장일) | C18: 65000 | D18: 공모가 20,000원 / 시초가 50,500원
B19: 2024.09.23 | C19: 29850 | D19: 상장일 종가 대비 -54% / 한국IR협의회 기준일
B20: 2025.05.29 | C20: 23350 | D20: SK증권 리포트 기준일
B21: 2025.12.15 | C21: 32850 | D21: 리딩투자증권 기준일 / 시가총액 4,950억원
B22: 2026.06 평균 | C22: 23332 | D22: 6월 최저 18,230원 (공모가 하회)
B25: 상장 시 공모가 산정 내역
B26: 구분 | C26: 내용
B27: 비교기업 | C27: ㈜라온테크 PER 33.83배 / 삼익THK㈜ PER 40.90배 → 적용 PER 37.37배
B28: 적용 이익 | C28: 2026년 추정 당기순이익 11,450백만원
B29: 현가 환산 | C29: 연 할인율 15% 적용 → 2023년말 현가 7,529백만원
B30: 적용 주식수 | C30: 15,601,881주
B31: 주당 평가가액 | C31: 18,030원
B32: 희망공모가 밴드 | C32: 11,000 ~ 15,000원 (평가액 대비 16.81~38.99% 할인)
B33: 확정 공모가 | C33: 20,000원
A34: ⚠️ 공모가는 2026년 추정 당기순이익 11,450백만원을 전제로 산정되었으나, 2026년 반기 실적은 순손실 3,665백만원
B37: 동종 업종 밸류에이션 (2024.09.23 기준)
B38: 기업명 | C38: 종가(원) | D38: 시가총액(십억원) | E38: PSR(배, 2024F) | F38: PBR(배, 2024F)
B39: 엔젤로보틱스 | C39: 29850 | D39: 446 | E39: 66.1 | F39: 13.2
B40: 삼익THK | C40: 9820 | D40: 206 | E40: 0.6 | F40: 1
B41: 알에스오토메이션 | C41: 11560 | D41: 108 | E41: 1.2 | F41: 3
B42: 코스닥 평균 | C42: 755 | D42: 372025 | E42: 1.8 | F42: 2.4
A43: 출처: Quantiwise, 한국IR협의회 기업리서치센터 / 최근 3개월간 한국거래소 시장경보제도 지정 이력 없음

Sheet 12_관리종목·시뮬레이션
A2: 관리종목 지정요건 및 자기자본 시뮬레이션
A3: 단위: 백만원 / 출처: 제10기 반기보고서 「관리종목 지정유예 현황」
B5: 요건별 유예 현황 (동사 공시 기준)
B6: 요건 | C6: 기준 | D6: 유예 종료 | E6: 적용 개시 | F6: 현황
B7: 매출액 | C7: 최근 사업연도 매출액 30억원 미만 | D7: 2028.12.31 | E7: 2029 사업연도 | F7: 2025년 4,641백만원 → 미해당
B8: 계속사업손실 | C8: 자기자본 50% 초과 세전손실이 최근 3년 중 2회 이상 및 최근 사업연도 손실 | D8: 2026.12.31 | E8: 2027 사업연도 | F8: 2025년 -29.8% → 미해당
B9: 자본잠식 | C9: 자본잠식률 50% 이상 또는 자기자본 10억원 미만 | D9: - | E9: - | F9: 자본금 7,696 / 자기자본 30,982 → 해당없음
B12: 세전손실 대비 자기자본 비율 (실적)
B13: 사업연도 | C13: 세전계속사업손익 (A) | D13: 자기자본 (B) | E13: 비율 (A/B) | F13: 요건 해당여부
B14: 2023년 | C14: -9239 | D14: 8678 | E14: =C14/D14 | F14: 미해당 (유예)
B15: 2024년 | C15: -10006 | D15: 40329 | E15: =C15/D15 | F15: 미해당
B16: 2025년 | C16: -9715 | D16: 32626 | E16: =C16/D16 | F16: 미해당
B19: 자기자본 및 판정비율 시뮬레이션
B20: 가정: 연간 세전손실 7,300백만원 (2026년 반기 실적 연간 환산) / 주식보상·옵션행사 유입 연 1,200백만원 / 2025년말 자기자본 32,626백만원 출발
C22: A안 : CPS 미발행 | E22: B안 : CPS 20,000백만원 발행
B23: 사업연도 | C23: 자기자본 | D23: 손실/자본 | E23: 자기자본 | F23: 손실/자본
B24: 2026년(E) | C24: =32626-$C$32+$C$33 | D24: =IF(C24<=0,"자본잠식",$C$32/C24) | E24: =32626+20000-$C$32+$C$33 | F24: =IF(E24<=0,"자본잠식",$C$32/E24)
B25: 2027년(E) | C25: =C24-$C$32+$C$33 | D25: =IF(C25<=0,"자본잠식",$C$32/C25) | E25: =E24-$C$32+$C$33 | F25: =IF(E25<=0,"자본잠식",$C$32/E25)
B26: 2028년(E) | C26: =C25-$C$32+$C$33 | D26: =IF(C26<=0,"자본잠식",$C$32/C26) | E26: =E25-$C$32+$C$33 | F26: =IF(E26<=0,"자본잠식",$C$32/E26)
B27: 2029년(E) | C27: =C26-$C$32+$C$33 | D27: =IF(C27<=0,"자본잠식",$C$32/C27) | E27: =E26-$C$32+$C$33 | F27: =IF(E27<=0,"자본잠식",$C$32/E27)
B28: 2030년(E) | C28: =C27-$C$32+$C$33 | D28: =IF(C28<=0,"자본잠식",$C$32/C28) | E28: =E27-$C$32+$C$33 | F28: =IF(E28<=0,"자본잠식",$C$32/E28)
B29: 2031년(E) | C29: =C28-$C$32+$C$33 | D29: =IF(C29<=0,"자본잠식",$C$32/C29) | E29: =E28-$C$32+$C$33 | F29: =IF(E29<=0,"자본잠식",$C$32/E29)
B32: 연간 세전손실 (가정) | C32: 7300
B33: 연간 자본 유입 (가정) | C33: 1200
A35: ※ 노란색 셀(C열 가정값)을 수정하면 시뮬레이션 전체가 재계산됨
A36: A안: 2028 사업연도에 판정비율이 50%를 초과하고 2029 사업연도 결산에서 최근 3년 중 2회가 성립하여 요건에 해당
A37: B안: 2031년까지 50%를 하회하여 투자자의 전환권 행사 가능 기간 전체를 커버
A38: ⚠️ 가정에 기초한 추정으로 실제 결과와 차이가 발생할 수 있으며, CPS의 자본 분류는 감사인 판단을 전제로 함
A39: 주) 실적표(위)의 비율은 공시 원문 표기를 따라 손실을 음수로 표시하였고, 시뮬레이션(아래)은 절대값 기준 양수로 표시함

Sheet 13_출처목록
A2: 자료 출처 목록
A3: 2026.08.25 기준
B5: 1차 자료 (공시)
B6: 자료명 | C6: 제출일 | D6: 성격 | E6: 활용 시트 | F6: 비고
B7: 제10기 반기보고서 | C7: 2026.08.14 | D7: 공시 원문 | E7: 01~04, 06~09, 11, 12 | F7: 최신·확정. 검토받은 반기재무제표
B8: 제9기 사업보고서 | C8: 2026.03.23 | D8: 공시 원문 | E8: 01, 03, 08 | F8: 감사의견 적정
B11: 2차 자료 (제3자 분석)
B12: 자료명 | C12: 작성일 | D12: 작성기관 | E12: 활용 시트 | F12: 비고
B13: 기업분석보고서 | C13: 2024.09.26 | D13: 한국IR협의회 기업리서치센터 | E13: 06, 09, 10, 11 | F13: 시장점유율·판매처·회수기간 도표 보유
B14: 기업분석 리포트 | C14: 2025.12.16 | D14: 리딩투자증권 | E14: 09, 10, 11 | F14: 가장 최신 증권사 리포트. Not Rated
B15: 기업분석 리포트 | C15: 2025.05.29 | D15: SK증권 | E15: 08, 10 | F15: 국가과제 리스트·엔젤라 플랫폼. Not Rated
B16: IPO 분석 리포트 | C16: 2024.03.06 | D16: 유진투자증권 | E16: 02, 10, 11 | F16: 침투율·공모가 산정·보호예수. 실적 전망은 outdated
B19: 웹 리서치 소스
B20: 항목 | C20: 기관/매체 | D20: 활용 시트 | E20: URL
B21: 국산 재활로봇 수가 미확보 이슈 | C21: 의학신문 | D21: 10 | E21: http://www.bosa.co.kr/news/articleView.html?idxno=2114946
B22: 로봇산업 실태조사 (국내 로봇산업 매출) | C22: 한국로봇산업진흥원 | D22: 10 | E22: https://www.kiria.org/portal/policysut/portalPlcyInquiry.do
B23: 로봇산업 실태조사 결과보고서 | C23: 공공데이터포털 | D23: 10 | E23: https://www.data.go.kr/data/3041731/fileData.do
B24: 고령인구 비율·장래인구추계 | C24: 국가데이터처 2025 고령자 통계 | D24: 10 | E24: https://www.kostat.go.kr/board.es?mid=a10301010000&bid=10820&list_no=438832
B25: 고령인구 100대 지표 | C25: KOSIS | D25: 10 | E25: https://kosis.kr/visual/nsportalStats/detailContents.do?listId=A&statJipyoId=3634
B26: 뇌졸중 환자수·재활 진료 통계 | C26: 건강보험심사평가원 의료빅데이터 | D26: 10 | E26: https://opendata.hira.or.kr/op/opc/selectMedInfoSvcList.do
B27: 재활로봇 보급사업·수가 체계 | C27: 국립재활원 재활연구소 | D27: 10 | E27: https://www.nrc.go.kr/research/html/content.do?depth=rp&menu_cd=03_04_00_01
B28: 외골격 웨어러블 로봇 시장 규모 | C28: Fortune Business Insights | D28: 10 | E28: https://www.fortunebusinessinsights.com/wearable-robotic-exoskeleton-market-104664
B29: 재활로봇 시장 규모 (대안 출처) | C29: GII Korea | D29: 10 | E29: https://www.giikorea.co.kr/report/gmi1858972-rehabilitation-robots-market-opportunity-growth.html
B30: 재활로봇 시장 규모 (대안 출처) | C30: Mordor Intelligence | D30: 10 | E30: https://www.mordorintelligence.kr/industry-reports/rehabilitation-robots-market
B31: 주가·거래 데이터 | C31: 한국거래소 정보데이터시스템 | D31: 11 | E31: http://data.krx.co.kr
A33: 주1) 웹 소스는 검색 결과 요약을 기반으로 하며, 본문 인용 시 원문 확인이 필요함
A34: 주2) DART·증권사·통계 사이트는 현재 작업 환경에서 직접 접속이 제한되어 1차 자료는 파일 업로드로 확보
B37: 미확보 항목 (발행사 확보 필요)
B38: 항목 | C38: 영향 범위 | D38: 우선순위
B39: 딜 조건 (규모·만기·금리·옵션) | C39: Term Sheet 전체 | D39: 높음
B40: CPS 자본분류 감사인 의견 | C40: 12_시뮬레이션 전제 | D40: 높음
B41: 아세안 수주 파이프라인 | C41: 해외 매출 논거 | D41: 높음
B42: BEP 매출 규모 | C42: 영업레버리지 논거 | D42: 높음
B43: 제품별 마진 | C43: 06_제품별매출 | D43: 중간
B44: 경쟁사 실명 및 최신 점유율 | C44: 10_시장·산업 | D44: 중간
B45: 침투율 최신화 (현재 2023년 기준) | C45: 10_시장·산업 | D45: 중간
