Workbook

Sheet 00_Overview
B2: 엔젤로보틱스㈜ (KOSDAQ 455900)
B3: 사모 CB·CPS 발행 검토 — 리서치 자료 집계
B5: 기준일 2026.08.26 / 재무수치 기준일 2026.06.30 (제10기 반기) / 제도·경쟁 정보는 2026.08 반영
B7: 1. 한눈에 보기
B8: 구분 | C8: 내용 | D8: 구분 | E8: 내용
B9: 설립 / 상장 | C9: 2017.02 / 2024.03.26 (기술특례) | D9: 대표이사 | E9: 조남민 (2024.10)
B10: 발행주식총수 | C10: 15,392,981주 | D10: 이사회 의장·CTO | E10: 공경철 (창업자)
B11: 최대주주등 | C11: 공경철 외 2인 27.48% | D11: 2대주주 | E11: LG전자 6.24%
B12: 2025년 매출 | C12: 4,641백만원 | D12: 2026년 반기 매출 | E12: 1,295백만원 (-49.4% YoY)
B13: 2025년 영업손실 | C13: (10,276)백만원 | D13: 2026년 반기 영업손실 | E13: (6,163)백만원
B14: 자기자본 (26.6말) | C14: 30,982백만원 | D14: 즉시 가용 유동성 | E14: 25,063백만원
B15: 차입금 | C15: 없음 | D15: 미상환 CB·BW | E15: 없음
B16: 국내 시장점유율 | C16: 56% (2023년, 2위 21%) | D16: 해외 인허가 | E16: 태국·베트남·말레이시아 (M20) / 말레이시아·베트남 (H10)
B17: 건강보험 수가 | C17: MM304 선별급여, 본인부담 50% | D17: 급여대상 확대 | E17: 2026.07.31 — 18세 이하 뇌성마비 등 중추신경계 질환
B20: 2. 시트 구성
B21: 시트 | C21: 내용 | D21: 주요 출처 | E21: 비고
B22: 01_회사개요·연혁 | C22: 기업 기본정보, 연혁 30건 | D22: 반기보고서
B23: 02_주주·경영진 | C23: 주주현황, 임원 8인, 스톡옵션 | D23: 반기보고서
B24: 03_손익계산서 | C24: 2020~2026 반기 손익 추이 | D24: 반기·사업보고서, 증권사 | E24: 가로형
B25: 04_재무상태표 | C25: 2020~2026 반기 재무상태 추이 | D25: 반기·사업보고서, 증권사 | E25: 가로형
B26: 05_재무비율 | C26: 안정성·수익성·성장성 지표 | D26: 03·04 시트 참조 산출 | E26: 전 항목 수식
B27: 06_제품별매출 | C27: 브랜드별·내수수출별 매출, 판매처 | D27: 반기보고서 원문 (우측 첨부) | E27: 가로형·수식 링크
B28: 07_추정치대비실적 | C28: 증권신고서 예측 대비 실적, 괴리사유 | D28: 반기보고서 원문 (우측 첨부)
B29: 08_R&D·국가과제 | C29: 연구개발비, 국고보조금, 과제 3건, 브레인투로봇 | D29: 반기보고서 원문 (우측 첨부) | E29: 가로형·수식 링크
B30: 09_인허가·수상 | C30: 해외 인허가, 국내 인허가, 기술 검증 이력 | D30: [인증현황] 시트 수식 참조 | E30: 행별 근거 표기
B31: 인증현황 | C31: 반기보고서 「바. 주요 인증 내역」 34건 원문 | D31: 반기보고서 원문 | E31: 09번의 원본
B32: 10_시장·산업 | C32: 시장규모, 인구·환자 통계, 수가 체계, 경쟁사 | D32: 증권사, 통계, 웹 (O열 URL) | E32: 가로형
B33: 11_주가·밸류에이션 | C33: 월별 주가, 공모가 산정, Peer | D33: [주가데이터] 시트 수식 참조 | E33: 가로형
B34: 주가데이터 | C34: 일별 주가·거래량 원문 | D34: 한국거래소 | E34: 11번의 원본
B35: 12_관리종목·시뮬레이션 | C35: 지정유예 현황, 자기자본 시뮬레이션 | D35: 반기보고서, 산출 | E35: 노란 셀 입력형
B36: 13_출처목록 | C36: 자료 8건 + 웹 소스 URL + 미확보 항목 | D36: -
B39: 3. 자료 등급 및 색상 규칙
B40: 구분 | C40: 의미
B41: 파란 글씨 | C41: 원문에서 그대로 입력한 값 (1차 자료)
B42: 검은 글씨 | C42: 수식 산출값 또는 서술
B43: 초록 글씨 | C43: 반기보고서 기준일(2026.06.30) 이후 확보한 신규 사실 — 공시 미반영
B44: 붉은 글씨 / ⚠ | C44: 1차 근거 미확보, 추정, 또는 인용 전 원문 대조가 필요한 항목
B45: 노란 셀 | C45: 사용자가 직접 수정하는 가정값 (12번 시트)
B46: O열 | C46: 해당 블록의 출처 URL
B47: 원문 시트 규칙 | C47: 공시 원문은 별도 시트 또는 표 우측에 그대로 붙여넣고, 정리표는 이를 수식으로 참조함. 원문을 갱신하면 정리표가 자동 반영됨

Sheet 01_회사개요·연혁
A2: 회사 개요 및 연혁
A3: 출처: 제10기 반기보고서(2026.08.14)
B5: 구분 | C5: 내용 | D5: 구분 | E5: 내용
B6: 회사명 | C6: 엔젤로보틱스 주식회사 | D6: 종목코드 | E6: 455900 (코스닥)
B7: 설립일 | C7: 2017년 2월 (구 ㈜에스지로보틱스) | D7: 상장일 | E7: 2024년 3월 26일
B8: 상장방식 | C8: 기술성장기업 특례상장 | D8: 인수인 | E8: NH투자증권
B9: 대표이사 | C9: 조남민 (2024.10 선임) | D9: 이사회 의장/CTO | E9: 공경철 (창업자)
B10: 자본금 | C10: 7,696,490,500원 | D10: 액면가 | E10: 500원
B11: 발행주식총수 | C11: 15,392,981주 | D11: 발행할 주식의 총수 | E11: 100,000,000주
B12: 본점 | C12: 서울 광진구 광나루로56길 85 테크노마트21 | D12: 감사인 | E12: 신한회계법인
B13: 사업장 | C13: 플래닛하남(생산, 24.04) / 플래닛대전(연구, 24.07) | D13: 종속회사 | E13: 없음 (별도 기준)
B14: 주요사업 | C14: 지능형 웨어러블 로봇 개발·제조·판매 및 국가연구개발 용역
B17: 주요 연혁
B18: 시기 | C18: 내용 | D18: 구분
B19: 2017.02 | C19: ㈜에스지로보틱스 설립 | D19: 회사설립
B20: 2017.05 | C20: LG전자 보통주 투자 유치 | D20: 투자유치
B21: 2018.02 | C21: 워크온슈트 평창 패럴림픽 성화봉송 지원 | D21: 경영활동
B22: 2018.09 | C22: ㈜엔젤로보틱스 사명 변경 | D22: 사명변경
B23: 2019.09 | C23: 의료기기 GMP 적합인정 획득 | D23: 인증
B24: 2020.01 | C24: Series A 97억원 투자 유치 | D24: 투자유치
B25: 2020.09 | C25: 엔젤렉스 M10 세브란스 재활병원 납품 | D25: 경영활동
B26: 2020.11 | C26: 제2회 사이배슬론 전동형 외골격 금메달·동메달 | D26: 수상
B27: 2021.07 | C27: Series B 180억원 투자 유치 | D27: 투자유치
B28: 2021.08 | C28: 엔젤렉스 M20 9개 병원 납품 | D28: 경영활동
B29: 2022.05 | C29: 말레이시아 UiTM 의과대학 전략적 협약(MOA) | D29: 협약체결
... B48: 2026.06 | C48: 범부처 '브레인 투 로봇' 개발 과제 주관기관 선정 | D48: 국가과제

Sheet 02_주주·경영진
A2: 주주 현황 및 경영진
A3: 기준일 2026.06.30 / 출처: 제10기 반기보고서
B5: 최대주주 및 특수관계인
B6: 성명 | C6: 관계 | D6: 주식수(주) | E6: 지분율
B7: 공경철 | C7: 본인 (이사회 의장/CTO) | D7: 3467560 | E7: 0.2256
B8: 나동욱 | C8: 임원 (임상총괄) | D8: 475680 | E8: 0.0309
B9: 정성훈 | C9: 기타 (공동목적보유확약) | D9: 281600 | E9: 0.0183
B10: 합계 | C10: - | D10: =SUM(D7:D9) | E10: =SUM(E7:E9)
B12: 주식 소유현황
B13: 구분 | C13: 주주명 | D13: 주식수(주) | E13: 지분율
B14: 5% 이상 주주 | C14: 공경철 | D14: 3467560 | E14: 0.2256
B15: 5% 이상 주주 | C15: LG전자 주식회사 | D15: 960000 | E15: 0.0624
B16: 우리사주조합 | C16: 우리사주조합 | D16: 119719 | E16: 0.0078
B17: 소액주주 | C17: 69,348명 | D17: 8730773 | E17: 0.568
B18: 발행주식총수 | C18: - | D18: 15392981 | E18: 1
A20: 주1) 최대주주 등은 코스닥 상장규정상 의무보유 1년을 거래소 협의를 통해 3년으로 자발 연장 (미행사 주식매수선택권은 1년 6개월)
A21: 주2) 설립 이후 최대주주 변동 없음 / 서강대학교산학협력단 2.28%, 연세대학교의료원산학협력단 0.29% 보유 (상장 시점 기준, 출처: 유진투자증권)
B24: 주요 경영진
B25: 성명 | C25: 직위 | D25: 선임 | E25: 구분 | F25: 주요 경력
B26: 조남민 | C26: 대표이사 (CEO) | D26: 2024.10 | E26: 사내이사 | F26: Medtronic Sr. Sales executive, ZimmerBiomet APAC Business Manager, Philips Korea GM, Trackman Greater Asia CEO
B27: 공경철 | C27: 이사회 의장/CTO | D27: 2017.02 | E27: 사내이사 | F27: UC Berkeley 기계공학 박사, 서강대 부교수, KAIST 기계공학과 교수
B28: 나동욱 | C28: 이사 (임상총괄) | D28: 2017.02 | E28: 미등기 | F28: 연세대 의대 재활의학 교수, 융합의학과 겸임교수
B29: 이수찬 | C29: 이사 (마케팅총괄) | D29: 2024.09 | E29: 미등기 | F29: 삼성전자, 현대오일뱅크, LG전자, 디케이메디칼시스템
B30: 황상탁 | C30: 이사 (인사총괄) | D30: 2025.11 | E30: 미등기 | F30: LG Display, SK Telecom, NCSOFT, 한국아스텔라스 이사
B31: 김주민 | C31: 이사 (영업총괄) | D31: 2026.02 | E31: 미등기 | F31: 한국존슨앤존슨메디칼, 메드트로닉코리아 이사 (22년)
B32: 장호식 | C32: 이사 (품질총괄) | D32: 2026.03 | E32: 미등기 | F32: 지멘스 헬시니어스 이사, 고영테크놀러지 상무
B33: 정동선 | C33: 이사 (재무총괄) | D33: 2026.04 | E33: 미등기 | F33: 한영회계법인 Manager, 이지홀딩스, 한울회계법인 회계사
B34: 김문성 | C34: 독립이사 | D34: 2022.05 | E34: 독립이사 | F34: 의정부지방법원 부장판사, 법무법인 이제 변호사
B35: 김미현 | C35: 독립이사 | D35: 2024.10 | E35: 독립이사 | F35: 사법시험·행정고시 합격, 법무법인(유한)광장
B36: 김인숙 | C36: 감사 | D36: 2024.03 | E36: 감사 | F36: 삼일회계법인 공인회계사, 검사, KB증권 사외이사
B39: 미행사 주식매수선택권
B40: 회차 | C40: 잔여수량(주) | D40: 행사가격(원) | E40: 행사가능 개시 | F40: 현 주가 대비
B41: 8회차 | C41: 125000 | D41: 8188 | E41: 2024.11.16 | F41: 내가격
B42: 9회차 | C42: 13500 | D42: 8188 | E42: 2025.06.01 | F42: 내가격
B43: 10회차 | C43: 22400 | D43: 8190 | E43: 2026.04.01 | F43: 내가격
B44: 11회차 | C44: 500000 | D44: 27069 | E44: 2027.10.17 | F44: 외가격
B45: 12회차 | C45: 253000 | D45: 28432 | E45: 2029.04.01 | F45: 외가격
B46: 합계 | C46: =SUM(C41:C45) | D46: - | E46: - | F46: =C46/15392981
A47: 주) 현 주가 대비 판정은 2026년 6월 평균 23,332원 기준

Sheet 03_손익계산서
A2: 손익계산서 추이 (K-IFRS 별도)
A3: 단위: 백만원 / 출처: 제10기 반기보고서, 제9기 사업보고서, SK증권·리딩투자증권
B5: 구분 | C5: 2020 | D5: 2021 | E5: 2022 | F5: 2023 | G5: 2024 | H5: 2025 | I5: 2025 반기 | J5: 2026 반기
B6: 매출액 | C6: 209 | D6: 814 | E6: 2184 | F6: 5146 | G6: 4211 | H6: 4641 | I6: 2562 | J6: 1295
B7: 매출원가 | C7: 128 | D7: 564 | E7: 1182 | F7: 2379 | G7: 1702 | H7: 2030 | I7: 932 | J7: 512
B8: 매출총이익 | C8: =C6-C7 | D8: =D6-D7 | E8: =E6-E7 | F8: =F6-F7 | G8: =G6-G7 | H8: =H6-H7 | I8: =I6-I7 | J8: =J6-J7
B9: 매출총이익률 | C9: =IFERROR(C8/C6,"") | D9: =IFERROR(D8/D6,"") | E9: =IFERROR(E8/E6,"") | F9: =IFERROR(F8/F6,"") | G9: =IFERROR(G8/G6,"") | H9: =IFERROR(H8/H6,"") | I9: =IFERROR(I8/I6,"") | J9: =IFERROR(J8/J6,"")
B10: 판매비와관리비 | C10: =C8-C11 | D10: =D8-D11 | E10: =E8-E11 | F10: =F8-F11 | G10: 13351 | H10: 12888 | I10: 6296 | J10: 6946
B11: 영업이익(손실) | C11: -2471 | D11: -4829 | E11: -7101 | F11: -6497 | G11: -10842 | H11: -10276 | I11: -4666 | J11: -6163
B12: 영업이익률 | C12: =IFERROR(C11/C6,"") | D12: =IFERROR(D11/D6,"") | E12: =IFERROR(E11/E6,"") | F12: =IFERROR(F11/F6,"") | G12: =IFERROR(G11/G6,"") | H12: =IFERROR(H11/H6,"") | I12: =IFERROR(I11/I6,"") | J12: =IFERROR(J11/J6,"")
B13: 금융수익 | G13: 1041 | H13: 851 | I13: 481 | J13: 2578
B14: 금융비용 | G14: 77 | H14: 129 | I14: 61 | J14: 65
B15: 법인세비용차감전순손실 | C15: -2472 | D15: -24094 | E15: -6797 | F15: -9239 | G15: -10006 | H15: -9715 | I15: -4405 | J15: -3665
B16: 당기순손실 | C16: -2472 | D16: -24094 | E16: -6797 | F16: -9239 | G16: -10006 | H16: -9715 | I16: -4405 | J16: -3665
B17: 주당순손실(원) | C17: -371 | D17: -3201 | E17: -770 | F17: -913 | G17: -687 | H17: -642 | I17: -292 | J17: -240
A19: 주1) 2020~2023년 매출원가는 SK증권 보고서의 매출총이익을 역산한 값이며, 판매비와관리비는 매출총이익에서 영업이익을 차감한 계산값임
A20: 주2) 2024·2025년 및 2026년 반기는 제9기 사업보고서·제10기 반기보고서 확정치, 2020~2023년은 증권사 보고서 기준
A21: 주3) 2026년 반기 매출액은 전년 동기 2,562백만원 대비 49.4% 감소
A22: 주4) 2024년 이후 판매비와관리비는 공시 확정치를 그대로 입력하였음. 2020~2023년만 '매출총이익 - 영업이익'으로 산출한 계산값임

Sheet 04_재무상태표
A2: 재무상태표 추이 (K-IFRS 별도)
A3: 단위: 백만원 / 출처: 제10기 반기보고서 「요약 별도 재무정보」, 리딩투자증권
B5: 구분 | C5: 2020 | D5: 2021 | E5: 2022 | F5: 2023 | G5: 2024 | H5: 2025 | I5: 2026 반기
B6: 유동자산 | C6: 5500 | D6: 18100 | E6: 12500 | F6: 17200 | G6: 34310 | H6: 28624 | I6: 28922
B7: 현금및현금성자산 | C7: 5200 | D7: 3100 | E7: 2100 | F7: 4200 | G7: 15064 | H7: 3151 | I7: 5053
B8: 단기금융상품 | C8: 0 | D8: 14000 | E8: 8200 | F8: 10400 | G8: 16000 | H8: 22000 | I8: 20010
B9: 매출채권 | C9: 0 | D9: 200 | E9: 400 | F9: 1000 | G9: 722 | H9: 723 | I9: 457
B10: 재고자산 | C10: 200 | D10: 500 | E10: 1200 | F10: 900 | G10: 1085 | H10: 1340 | I10: 1308
B11: 비유동자산 | C11: 1000 | D11: 4100 | E11: 4000 | F11: 4100 | G11: 9567 | H11: 8409 | I11: 7344
B12: 유형자산 | C12: 500 | D12: 3400 | E12: 3300 | F12: 3100 | G12: 3511 | H12: 4070 | I12: 4023
B13: 무형자산 | C13: 200 | D13: 200 | E13: 300 | F13: 700 | G13: 1031 | H13: 870 | I13: 793
B14: 자산총계 | C14: =C6+C11 | D14: =D6+D11 | E14: =E6+E11 | F14: =F6+F11 | G14: =G6+G11 | H14: =H6+H11 | I14: =I6+I11
B15: 유동부채 | C15: 100 | D15: 34600 | E15: 34700 | F15: 11000 | G15: 1135 | H15: 1222 | I15: 1892
B16: 비유동부채 | C16: 300 | D16: 1500 | E16: 1500 | F16: 1600 | G16: 2413 | H16: 3186 | I16: 3392
B17: 부채총계 | C17: =C15+C16 | D17: =D15+D16 | E17: =E15+E16 | F17: =F15+F16 | G17: =G15+G16 | H17: =H15+H16 | I17: =I15+I16
B18: 자본금 | G18: 7496 | H18: 7609 | I18: 7696
B19: 자본잉여금 | G19: 90007 | H19: 91979 | I19: 94049
B20: 결손금 | G20: -59467 | H20: -69098 | I20: -72763
B21: 자본총계 | C21: =C14-C17 | D21: =D14-D17 | E21: =E14-E17 | F21: =F14-F17 | G21: =G14-G17 | H21: =H14-H17 | I21: =I14-I17
B23: 즉시 가용 유동성 (현금+단기금융상품) | C23: =C7+C8 | D23: =D7+D8 | E23: =E7+E8 | F23: =F7+F8 | G23: =G7+G8 | H23: =H7+H8 | I23: =I7+I8
B24: 금융기관 차입금 | C24: - | D24: - | E24: - | F24: - | G24: - | H24: - | I24: -
A26: 주1) 2024·2025년 및 2026년 반기는 제10기 반기보고서 「요약 별도 재무정보」 확정치
A27: 주2) 2020~2023년은 리딩투자증권 보고서의 억원 단위 표기를 백만원으로 환산한 근사치이므로 소수점 이하 정밀도가 낮음
A28: 주3) 2021~2022년 자본총계가 음(-)인 것은 상장 전 발행한 상환전환우선주(RCPS)가 부채로 계상되었기 때문이며, 2023년 보통주 전환으로 해소됨
A29: 주4) 2026년 반기말 기준 금융기관 차입금·회사채·기업어음·단기사채 미상환 잔액이 모두 없음 (반기보고서 「채무증권 발행실적」)

Sheet 05_재무비율
A2: 주요 재무비율
A3: 출처: 03_손익계산서·04_재무상태표 기준 산출
B5: 구분 | C5: 2020 | D5: 2021 | E5: 2022 | F5: 2023 | G5: 2024 | H5: 2025 | I5: 2026 반기
B6: 부채비율 | C6: =IFERROR('04_재무상태표'!C17/'04_재무상태표'!C21,"") | D6: =IFERROR('04_재무상태표'!D17/'04_재무상태표'!D21,"") | E6: =IFERROR('04_재무상태표'!E17/'04_재무상태표'!E21,"") | F6: =IFERROR('04_재무상태표'!F17/'04_재무상태표'!F21,"") | G6: =IFERROR('04_재무상태표'!G17/'04_재무상태표'!G21,"") | H6: =IFERROR('04_재무상태표'!H17/'04_재무상태표'!H21,"") | I6: =IFERROR('04_재무상태표'!I17/'04_재무상태표'!I21,"")
B7: 유동비율 | C7: =IFERROR('04_재무상태표'!C6/'04_재무상태표'!C15,"") | D7: =IFERROR('04_재무상태표'!D6/'04_재무상태표'!D15,"") | E7: =IFERROR('04_재무상태표'!E6/'04_재무상태표'!E15,"") | F7: =IFERROR('04_재무상태표'!F6/'04_재무상태표'!F15,"") | G7: =IFERROR('04_재무상태표'!G6/'04_재무상태표'!G15,"") | H7: =IFERROR('04_재무상태표'!H6/'04_재무상태표'!H15,"") | I7: =IFERROR('04_재무상태표'!I6/'04_재무상태표'!I15,"")
B8: 자기자본비율 | C8: =IFERROR('04_재무상태표'!C21/'04_재무상태표'!C14,"") | D8: =IFERROR('04_재무상태표'!D21/'04_재무상태표'!D14,"") | E8: =IFERROR('04_재무상태표'!E21/'04_재무상태표'!E14,"") | F8: =IFERROR('04_재무상태표'!F21/'04_재무상태표'!F14,"") | G8: =IFERROR('04_재무상태표'!G21/'04_재무상태표'!G14,"") | H8: =IFERROR('04_재무상태표'!H21/'04_재무상태표'!H14,"") | I8: =IFERROR('04_재무상태표'!I21/'04_재무상태표'!I14,"")
B9: 매출총이익률 | C9: =IFERROR('03_손익계산서'!C8/'03_손익계산서'!C6,"") | D9: =IFERROR('03_손익계산서'!D8/'03_손익계산서'!D6,"") | E9: =IFERROR('03_손익계산서'!E8/'03_손익계산서'!E6,"") | F9: =IFERROR('03_손익계산서'!F8/'03_손익계산서'!F6,"") | G9: =IFERROR('03_손익계산서'!G8/'03_손익계산서'!G6,"") | H9: =IFERROR('03_손익계산서'!H8/'03_손익계산서'!H6,"") | I9: =IFERROR('03_손익계산서'!J8/'03_손익계산서'!J6,"")
B10: 영업이익률 | C10: =IFERROR('03_손익계산서'!C11/'03_손익계산서'!C6,"") | D10: =IFERROR('03_손익계산서'!D11/'03_손익계산서'!D6,"") | E10: =IFERROR('03_손익계산서'!E11/'03_손익계산서'!E6,"") | F10: =IFERROR('03_손익계산서'!F11/'03_손익계산서'!F6,"") | G10: =IFERROR('03_손익계산서'!G11/'03_손익계산서'!G6,"") | H10: =IFERROR('03_손익계산서'!H11/'03_손익계산서'!H6,"") | I10: =IFERROR('03_손익계산서'!J11/'03_손익계산서'!J6,"")
B11: 세전손실 / 자기자본 | C11: =IFERROR('03_손익계산서'!C15/'04_재무상태표'!C21,"") | D11: =IFERROR('03_손익계산서'!D15/'04_재무상태표'!D21,"") | E11: =IFERROR('03_손익계산서'!E15/'04_재무상태표'!E21,"") | F11: =IFERROR('03_손익계산서'!F15/'04_재무상태표'!F21,"") | G11: =IFERROR('03_손익계산서'!G15/'04_재무상태표'!G21,"") | H11: =IFERROR('03_손익계산서'!H15/'04_재무상태표'!H21,"") | I11: =IFERROR('03_손익계산서'!J15/'04_재무상태표'!I21,"")
A13: 주1) 마지막 열은 2026년 반기 손익을 2026년 반기말 재무상태와 대응시킨 것으로, 연간 환산치가 아님
A14: 주2) 세전손실/자기자본 비율은 코스닥 관리종목 계속사업손실 요건의 판정 지표임 (12_관리종목·시뮬레이션 참조)
A15: 주3) 2020~2023년은 근사 환산치 기반이므로 참고용

Sheet 06_제품별매출
A2: 제품별 매출 실적
B5: 매출 비중 | K5: 단위 : 천원 | P5: 가. 매출 실적
C6: 매출유형 | D6: 품목 | E6: 2022 | F6: =+E6+1 | G6: =+F6+1 | H6: =+G6+1 | I6: 2026 반기 | J6: 2025 비중 | K6: 2026반기 비중 | AB6: 가.매출실적
C7: 제품매출 | D7: angel MEDI (내수) | E7: =+X11 | F7: =+Z11 | G7: =+AE11 | H7: =+AF11 | I7: =+AG11 | J7: =IFERROR(H7/H$14,"") | K7: =IFERROR(I7/I$14,"") | P7: (단위: 천 원) | AB7: (단위:천원)
C8: 제품매출 | D8: angel MEDI (수출) | E8: 0 | F8: 0 | G8: 0 | H8: =+AF12 | I8: =+AG12 | J8: =IFERROR(H8/H$14,"") | K8: =IFERROR(I8/I$14,"") | P8: 매출유형 | Q8: 품목 | S8: 2020년 | U8: 2021년 | W8: 2022년 | Y8: 2023년 | AB8: 매출유형 | AC8: 품목 | AE8: 2024년 | AF8: 2025년 | AG8: 2026년6월말
C9: 제품매출 | D9: angel SUIT | E9: =+X13 | F9: =+Z13 | G9: =+AE15 | H9: =+AF15 | I9: =+AG15 | J9: =IFERROR(H9/H$14,"") | K9: =IFERROR(I9/I$14,"") | S9: (제4기) | U9: (제5기) | W9: (제6기) | Y9: (제7기) | AE9: (제8기) | AF9: (제9기) | AG9: (제10기반기)
C10: 제품매출 | D10: angel GEAR | E10: =+X12 | F10: =+Z12 | G10: =+AE14 | H10: =+AF14 | I10: =+AG14 | J10: =IFERROR(H10/H$14,"") | K10: =IFERROR(I10/I$14,"") | S10: 수량 | T10: 금액 | U10: 수량 | V10: 금액 | W10: 수량 | X10: 금액 | Y10: 수량 | Z10: 금액 | AE10: 금액 | AF10: 금액 | AG10: 금액
C11: 제품매출 | D11: angel KIT | E11: 0 | F11: =+Z14 | G11: =+AE16 | H11: =+AF16 | I11: 0 | J11: =IFERROR(H11/H$14,"") | K11: =IFERROR(I11/I$14,"") | P11: 제품매출 | Q11: angelMEDI | R11: 내수 | S11: 1 | T11: 104454 | U11: 9 | V11: 502182 | W11: 21 | X11: 1543489 | Y11: 39 | Z11: 3088704 | AB11: 제품매출 | AD11: 내수 | AE11: 3129220 | AF11: 1445568 | AG11: 649568
C12: 용역매출 | D12: 웨어러블로봇 개발용역 | E12: =+X20 | F12: =+Z20 | G12: =+AE19 | H12: =+AF19 | I12: =+AG19 | J12: =IFERROR(H12/H$14,"") | K12: =IFERROR(I12/I$14,"") | Q12: angelGEAR | R12: 내수 | S12: - | T12: - | U12: - | V12: - | W12: 113 | X12: 107608 | Y12: 1304 | Z12: 1341189 | AC12: ㅙ | AD12: 수출 | AE12: - | AF12: 241238 | AG12: 125252
C13: 용역매출 | D13: 유상유지보수 | E13: 0 | F13: 0 | G13: =+AE20 | H13: =+AF20 | I13: =+AG20 | J13: =IFERROR(H13/H$14,"") | K13: =IFERROR(I13/I$14,"") | Q13: angelSUIT | R13: 내수 | S13: - | T13: - | U13: 3 | V13: 72273 | W13: 4 | X13: 88320 | Y13: 4 | Z13: 138450 | AD13: 소계 | AE13: 3129220 | AF13: 1686806 | AG13: 774820
C14: 합계 | D14: - | G14: =SUM(G7:G13) | H14: =SUM(H7:H13) | I14: =SUM(I7:I13) | J14: =IFERROR(H14/H14,"") | K14: =IFERROR(I14/I14,"") | Q14: angelKIT | R14: 내수 | S14: - | T14: - | U14: - | V14: - | W14: - | X14: - | Y14: 11 | Z14: 94646 | AC14: angelGEAR | AD14: 내수 | AE14: 247706 | AF14: 120680 | AG14: 30474
Q15: 워크온슈트 | R15: 내수 | S15: - | T15: - | U15: 1 | V15: 141545 | W15: - | X15: - | Y15: - | Z15: - | AC15: angelSUIT | AD15: 내수 | AE15: 368678 | AF15: 1380488 | AG15: 192310
C16: 수출 비중(전체) | D16: 0 | E16: 0 | F16: 0 | G16: =G8/G14 | H16: =H8/H14 | I16: =I8/I14 | Q16: 소계 | R16: 내수 | S16: - | T16: - | U16: 13 | V16: 716000 | W16: 138 | X16: 1739417 | Y16: 1358 | Z16: 4662989 | AC16: angelKIT | AD16: 내수 | AE16: 25922 | AF16: 116359 | AG16: -
C17: 수출 비중(제품매출 내) | D17: 0 | E17: 0 | F17: 0 | G17: =G8/SUM(G7:G11) | H17: =H8/SUM(H7:H11) | I17: =I8/SUM(I7:I11) | Q17: 국방부웨어러블슈트연구개발 | R17: 내수 | S17: - | T17: - | U17: (주1) | V17: 38692 | W17: (주1) | X17: 444895 | Y17: (주1) | Z17: 451731 | AC17: 소계 | AD17: 내수 | AE17: 3771526 | AF17: 3063095 | AG17: 872352
P18: 용역매출 | Q18: LG전자로봇핸드용구동모듈개발 | R18: 내수 | Y18: (주1) | Z18: 31466 | AD18: 수출 | AE18: - | AF18: 241238 | AG18: 125252
B19: 판매처 구성 (2023년) | Q19: 택배상하차근력보조로봇개발 | R19: 내수 | S19: - | T19: - | U19: (주1) | V19: 59237 | W19: - | X19: - | Y19: - | Z19: - | AB19: 용역매출 | AC19: 웨어러블로봇개발용역등 | AD19: 내수 | AE19: 419412 | AF19: 757595 | AG19: 43819
C20: 판매처 | D20: 비중 | E20: 판매처 | F20: 비중 | Q20: 소계 | R20: 내수 | S20: - | T20: 104454 | U20: (주1) | V20: 97929 | W20: (주1) | X20: 444895 | Y20: (주1) | Z20: 483197 | AC20: 유상유지보수 | AD20: 내수 | AE20: 20016 | AF20: 579384 | AG20: 253925
C21: 회복기재활의료기관 | D21: 0.38 | E21: 재활병원 | F21: 0.1 | P21: 합계 | R21: 내수 | S21: 1 | T21: 104454 | U21: 13 | V21: 813929 | W21: 138 | X21: 2184312 | Y21: 1358 | Z21: 5146186 | AC21: 소계 | AD21: 내수 | AE21: 439428 | AF21: 1336979 | AG21: 297744
C22: 상급종합병원 | D22: 0.21 | E22: 요양병원 | F22: 0.08 | AB22: 합계 | AD22: - | AE22: 4210954 | AF22: 4641312 | AG22: 1295348
C23: 장애인복지관 | D23: 0.1 | E23: 대학교 | F23: 0.03
C24: 재활학교 | D24: 0.1 | E24: 합계 | F24: 1
A25: 출처: 엔젤로보틱스, 한국IR협의회 기업리서치센터(2024.09.26)

Sheet 07_추정치대비실적
A2: 증권신고서 추정치 대비 실적 | M2: 파. 특례상장기업의 사후정보
M4: (1) 상장기업의 재무사항 비교표
C5: 구분 | D5: 예측치 | E5: 실적치 | F5: 달성 여부 | G5: 괴리율 | M5: (기준 재무제표 : | N5: 별도 | O5: ) | P5: (상장일 : | Q5: 45377 | R5: , 인수인 : | S5: NH투자증권 | T5: ) | U5: (단위 : 백만원)
C6: 2024년 매출액 | D6: 9016 | E6: 4211 | F6: 미달성 | G6: 0.5329 | M6: 추정대상 | N6: 계정과목 | O6: 예측치 | P6: 실적치 | Q6: 예측치 달성 | R6: 괴리율
C7: 2024년 영업이익 | D7: -5141 | E7: -10842 | F7: 미달성 | G7: 1.1089 | Q7: 여부
C8: 2024년 당기순이익 | D8: -4407 | E8: -10006 | F8: 미달성 | G8: 1.2705 | M8: 2024년 | N8: 매출액 | O8: 9016 | P8: 4211 | Q8: 미달성 | R8: 53.29
C9: 2025년 매출액 | D9: 20842 | E9: 4641 | F9: 미달성 | G9: 0.7773 | N9: 영업이익 | O9: -5141 | P9: -10842 | Q9: 미달성 | R9: 110.89
C10: 2025년 영업이익 | D10: 1766 | E10: -10276 | F10: 미달성 | G10: 6.8188 | N10: 당기순이익 | O10: -4407 | P10: -10006 | Q10: 미달성 | R10: 127.05
C11: 2025년 당기순이익 | D11: 2364 | E11: -9715 | F11: 미달성 | G11: 5.1096 | M11: 2025년 | N11: 매출액 | O11: 20842 | P11: 4641 | Q11: 미달성 | R11: 77.73
C12: 2026년 매출액 | D12: 36179 | F12: - | N12: 영업이익 | O12: 1766 | P12: -10276 | Q12: 미달성 | R12: 681.88
C13: 2026년 영업이익 | D13: 10643 | F13: - | N13: 당기순이익 | O13: 2364 | P13: -9715 | Q13: 미달성 | R13: 510.96
C14: 2026년 당기순이익 | D14: 11450 | F14: - | M14: 2026년 | N14: 매출액 | O14: 36179 | P14: - | Q14: - | R14: -
N15: 영업이익 | O15: 10643 | P15: - | Q15: - | R15: -
N16: 당기순이익 | O16: 11450 | P16: - | Q16: - | R16: -
M17: 주1) 당사는 2024년 3월 26일 코스닥시장 상장규정 제7조(신규상장심사요건의 특례)의 2항에 의하여 '기술특례상장'하였습니다. 위 표에서의 '예측치'는 2024년 03월 상장 공모를 위하여 제출한 증권신고서에 작성된 미래 영업실적의 추정치이며, '실적치'는 각 사업연도의 기록된 재무제표 기준의 실적입니다. 또한 '괴리율'은 [(예측치-실적치)/예측치]로 산정하였습니다.
B18: 주1) 괴리율 = (예측치 - 실적치) / 예측치 | M18: 주2) 2024년 실적의 괴리율 발생 사유
B19: 주2) 회사가 공시한 괴리 사유: ① 의정갈등 장기화에 따른 의료기관 투자 위축 ② 유럽 CE MDR 인증 지연에 따른 수출 발생 지연 ③ 정부 주도 산업안전 웨어러블 로봇 보급 예산 감소
B20: 주3) 2025년 매출 미달분 중 인증 지연 요인이 24%p를 차지하며, 해당 요인은 아세안 3개국 인허가 완결로 해소 | M20: - 당사 매출은 재활의료시장의 성장과 해외 진출의 확대 등을 예상하여 2024년 실적을 예상하였으나 의정갈등사태 장기화에 따른 국내 의료시장의 위축 및 예산부족 현상으로 인해 재활 웨어러블 로봇 시장이 위축되며 당사의 매출성장에 악영향을 끼쳐 53.29% 미달하였습니다.
M22: [괴리사유 상세분석]
M24: 매출항목 | N24: 2024년
M25: angel MEDI | N25: 발생사유 | O25: - 예상하지 못한 의정갈등사태의 장기화에 따른 국내의료시장의 위축(53%)
O26: - 해외 인증 지연에 따른 해외 수출 발생 지연(3%)
N27: 상세내역 | O27: - 2024년 예상하지 못한 의정갈등사태로 인해 상급종합병원 등의 투자 지연 및 예산부족현상 발생
O28: - 유럽 CE MDR 인증 지연에 따른 말레이시아, 태국, 싱가폴, 홍콩 등 APAC 지역 해외수출 지연
M29: angel GEAR | N29: 발생사유 | O29: - 정부주도(B2G) 산업용 웨어러블로봇 보급 시장 축소(27%)
O30: - 민간주도(B2B) 산업용 웨어러블로봇 시장 개화 지연(2%)
N31: 상세내역 | O31: - '스마트 안전장비 보급확산' 사업 등 정부주도의 산업용 웨어러블로봇 보급을 위한 정부보조금 감소에 따른 B2G 시장의 축소
O32: - 대기업 위주의 현장중심 산업용 웨어러블로봇 개발 진행 중이나 시장이 아직 개화기로서 예상보다 더딘 상용화 및 대량 보급
M33: 용역매출 | N33: 발생사유 | O33: - 국방용 웨어러블 로봇 개발 용역 발주 지연 (6%)
N34: 상세내역 | O34: - 예상된 국방용 웨어러블 로봇 개발 용역의 발주가 2025년으로 지연됨에 따른 용역 매출 괴리 발생
M36: - 영업이익과 순이익은 상장 이후 해외진출 준비를 위한 마케팅 세일즈 비용 증가와 생산시설 고도화 및 연구시설 설립으로 인한 투자 및 전문 인력확대 비용 발생, 신제품 개발을 위한 경상연구개발비용 증가 등으로 인해 예측치 대비 각각 110.89%, 127.05% 미달하였습니다.
M37: 주3) 2025년 실적의 괴리율 발생 사유
M39: - 당사 매출은 과거 국내 재활로봇시장의 성장율과 마켓리서치 기관의 웨어러블로봇 시장의 가파른 성장 예측을 기반으로 하여 당사 주력제품인 엔젤메디의 정형/신경외과로의 횡적인 시장확대, CE 등 해외 인증을 통한 해외 수출 시장 개척과 정부주도 하의 산업 안전용 웨어러블 로봇 시장 성장 및 엔젤슈트 등의 신제품 출시를 반영하여 2025년 실적을 예측하였으나, 예상 밖의 의정갈등 및 정치불안에 따른 의료시장의 투자 위축 및 해외 인증 지연과 함께 산업용 웨어러블 제품에 대한 정부 지원 감소 등이 당사의 매출성장에 악영향을 끼쳐 기존 예측치 대비 77.73% 미달하였습니다.
M41: [괴리사유 상세분석]
M42: 매출항목 | N42: 2025년
M43: angel MEDI | N43: 발생사유 | O43: - 의정갈등사태, 정치불안에 따른 국내 의료시장의 투자 위축 (57%)
O44: - 유럽 등 해외 인증 지연에 따른 해외 수출 감소 (24%)
N45: 상세내역 | O45: - 의정갈등사태 및 정치불안의 지속에 따른 주요 고객인 (상급)종합병원을 비롯한 재활의료기관의 투자위축으로 angel MEDI M20의 국내 판매 저하
O46: - 유럽 CE MDR 인증 지연으로 인해 태국, 베트남 및 말레이시아 시장 위주의 공략으로 예측치 대비 수출 실적 감소
M47: angel SUIT | N47: 발생사유 | O47: - 2025년 5월 정식 출시 이후 예측치 대비 2.8억원 실적치 상회 (-2%)
...

Sheet 08_R&D·국가과제
A2: 연구개발비 및 국가연구개발과제
K3: (4) 연구개발 비용
R4: (단위: 원)
B5: 연구개발비용 | K5: (단위: 천 원 | R5: 구분 | T5: 2024년 | U5: 2025년 | V5: 2026년 반기
C6: 구분 | D6: 2022 | E6: 2023 | F6: 2024 | G6: 2025 | H6: 2026 반기 | K6: 구분 | M6: 2020년 | N6: 2021년 | O6: 2022년 | P6: 2023년 | T6: (제8기) | U6: (제9기) | V6: (제10기 반기)
C7: 인건비 | D7: =+O7 | E7: =+P7 | F7: =(+T7)/1000 | G7: =(+U7)/1000 | H7: =(+V7)/1000 | K7: 비용처리 | L7: 인건비 | M7: 794408 | N7: 859175 | O7: 1630738 | P7: 1909715 | R7: 비용처리 | S7: 인건비 | T7: 2103821330 | U7: 2586177294 | V7: 1287276904
C8: 재료비·외주비 | D8: =+O8 | E8: =+P8 | F8: =(+T8)/1000 | G8: =(+U8)/1000 | H8: =(+V8)/1000 | L8: 재료비/외주비 | M8: 786724 | N8: 1201669 | O8: 1830186 | P8: 1468212 | S8: 재료비/외주비 | T8: 1529244201 | U8: 1862472197 | V8: 807686052
C9: 연구개발비 합계 | D9: =+O9 | E9: =+P9 | F9: =(+T9)/1000 | G9: =(+U9)/1000 | H9: =(+V9)/1000 | L9: 합계 | M9: 1581132 | N9: 2060844 | O9: 3460924 | P9: 3377927 | S9: 합계 | T9: 3633065531 | U9: 4448649491 | V9: 2094962956
C10: 국고보조금 | D10: =+O10 | E10: =+P10 | F10: =(+T10)/1000 | G10: =(+U10)/1000 | H10: =(+V10)/1000 | L10: 국고보조금 | M10: -1104789 | N10: -990007 | O10: -1585061 | P10: -2183357 | S10: 국고보조금 | T10: -1202138423 | U10: -1730818730 | V10: -765828492
C11: 보조금 차감 후 | D11: =+O11 | E11: =+P11 | F11: =(+T11)/1000 | G11: =(+U11)/1000 | H11: =(+V11)/1000 | L11: 차감 후 합계 | M11: 476343 | N11: 1070837 | O11: 1875863 | P11: 1194570 | S11: 차감 후 합계 | T11: 2430927108 | U11: 2717830761 | V11: 1329134464
C12: 매출액 | D12: =+O12 | E12: =+P12 | F12: =(+T12)/1000 | G12: =(+U12)/1000 | H12: =(+V12)/1000 | K12: 매출액 | M12: 208909 | N12: 813929 | O12: 2184312 | P12: 5146186 | R12: 매출액 | T12: 4210953924 | U12: 4641312180 | V12: 1295353725
C13: 매출액 대비 R&D 비율 | D13: =+D9/D12 | E13: =+E9/E12 | F13: =+F9/F12 | G13: =+G9/G12 | H13: =+H9/H12 | K13: (매출액 대비국고보조금 | M13: 7.5685 | N13: 2.532 | O13: 1.5844 | P13: 0.6564 | R13: (매출액 대비국고보조금 | T13: 0.8628 | U13: 0.9585 | V13: 1.6173
K14: 차감 전 연구개발비율) | R14: 차감 전 연구개발비율)
B16: 수행 중인 국가연구개발과제 (2026년 반기 기준) | K16: 투자판단 관련 주요경영사항
C17: 과제명 | D17: 연구개발기간 | E17: 비고 | K17: 1. 제목 | M17: 국책과제 선정(체내이식형 뇌-AI-로봇 실시간 연동 시스템 개발)
C18: 운동-감각 동기화가 가능한 Brain-to-Robot 풀스택 시스템 개발 및 상용화 | D18: 2026.04~2032.12 | E18: 수행중 (주관기관) | K18: 2. 주요내용 | M18: 당사는 산업통상부에서 주관하는 '범부처첨단의료기기연구개발'의 주관기관으로 주요 내용은 다음과 같습니다.
C19: AI 기반의 웨어러블 로봇의 개인화 및 정밀건강 진단 서비스 개발 | D19: 2026.05~2027.04 | E19: 수행중 | M19: 1.과제명 : 운동-감각 동기화가 가능한 Brain-to-Robot 풀스텍 시스템 개발 및 상용화
C20: 소방대원 활동성 등 수행능력 지원을 위한 외골격 로보틱 슈트 개발 | D20: 2026.04~2028.12 | E20: 수행중 | M20: 2.전담기관: 범부처의료기기연구개발사업단
M21: - 주관기관 : (주)엔젤로보틱스
C22: 과거 수행 과제 (2024년 사업보고서 기준, 참고) | M22: - 참여기관 :한국과학기술원, 서울대학교산학협력단, 한국산업기술시험원 등 10개 기관
C23: 웨어러블 로봇의 헬스케어 시장 확장을 위한 비즈니스 인프라 개발 | D23: 2025.01~2025.12 | M23: 3.과제수행기간 : 2026.04.01 ~ 2032.12.31(6년 9개월)
C24: 코어리스 마이크로모터 제조기술 개발 및 성능 검증 | D24: 2024.10~2028.12 | M24: 4.사업비
C25: AI 기반 로봇을 위한 Sim-to-real 수준의 고토크-무저항 구동모듈 개발 | D25: 2024.07~2026.12 | M25: 1)총 사업비 : 235.47억원
C26: 조선소 Yard 위보기 용접 보조용 스마트 웨어러블 슈트 제품화 | D26: 2024.07~2026.12 | M26: 2)총 정부출연금 : 202.5억원(당사: 69.9억원)
C27: 가정과 일상 헬스케어 시장을 위한 웨어러블 로봇 제품 및 서비스 플랫폼 개발 | D27: 2022.04~2025.12 | M27: 3)총 민간부담금 : 33.2억원(당사: 23.3억원)
C28: 착용형 보행보조로봇 기반 재택 보행 재활 서비스 모델 개발 및 실증 | D28: 2023.07~2025.12 | M28: 4)자기자본 :32,626,209,747원
B29: 출처: SK증권 기업분석(2025.05.29), 2024년 사업보고서 기준 | M29: 5)자기자본 대비 당사분 정부지원연구개발비 비율: 21.4%
M30: 5.사업내용 및 기대효과
B31: 양방향 Brain-to-Robot | M31: 1)과제목표 :
C32: - `26년 6월 범부처 첨단 의료기기 연구개발 사업의 플래그십 과제 주관기관 선정 | M32: ㅇ 사지마비 장애인의 보행 및 조작 기능 복원을 위하여 고해상도 피질내 전극 기반의 양방향 뇌신경 인터페이스와 인간의 운동 제어 계층을 모사한 로봇 제어 아키텍처가 유기적으로 통합된, 감각 인코딩와 의도 디코딩을 동시에 수행하며 로봇을 제어하는 세계 최초의 양방향 Brain-to-Robot 기술을 개발함
C33: - 총사업비 235.5억원(정부출연금 202.5억원) 규모로 한국과기원 등 10개 기관이 참여 | M33: 2) 기대효과
C34: - 동사는 컨소시엄 촐괄 및 전신 착용형 외골격 로봇 개발 | M34: ㅇ Brain-to-Robot 융합을 통한 신산업 생태계 및 명확한 기술 방향성 제시
M35: ㅇ 뇌-로봇 통합 제어(Brain-to-Robot) 원천 기술 확보
C36: >>단계별 개발계획 | M36: ㅇ 체내이식형 의료기기 분야의 선제적 규제 가이드라인 확립이식형 의료기기의 기술적 한계를 극복하는 고신뢰성 하드웨어 기술 내재화
C37: 핵심목표 | D37: 기간 | E37: 산출물 | K37: 3. 사실발생(확인)일 | M37: 46185
C38: 1. 요소기술 확보 | D38: 2026-2027 | E38: - Brain-to-Robot 전용 외골격 로봇 핵심요소, 실시간 제어 아키텍처 | K38: 4. 결정일 | M38: 46185
C39: 2. 통합 및 최초 인체 임상 | D39: 2028-2029 | E39: - HW/SW 통합 시스템, 임상시험용 기기
C40: 3 . 식약처 인허가 및 상용화 | D40: 2030-2032 | E40: - 조합의료기기 인허가, 초기 상용 제품

Sheet 09_인허가·수상
A2: 인허가 및 기술 검증 이력
A3: 1차 출처: 제10기 반기보고서(2026.06.30) — 「바. 주요 인증 내역」은 [인증현황] 시트에 원문 수록, 아래 표의 인증일·유효기간은 해당 시트를 수식 참조
A5: x | B5: 해외 인허가 현황 | O5: https://zdnet.co.kr/view/?no=20260805083950
C6: 국가/지역 | D6: 규제기관 | E6: 대상 제품 | F6: 인증일 | G6: 유효기간 | H6: 현황 | I6: 근거 (행별) | O6: 출처: 반기보고서 「바. 주요 인증 내역」·연혁·사업의 내용 / 2026.08 베트남 H10은 언론 보도
C7: 태국 | D7: TFDA | E7: =+인증현황!C73 | F7: =+인증현황!D71 | G7: =+인증현황!D72 | H7: 2025.06 인증 획득 → 수출 개시 | I7: 인증현황 No.28 + 연혁 「2025.06 태국 TFDA 인증 획득」
C8: 베트남 | D8: 보건복지부(MOH) | E8: =+인증현황!C76 | F8: =+인증현황!D74 | G8: =+인증현황!D75 | H8: 2025.07 인증 획득 → 수출 개시 | I8: 인증현황 No.29 + 연혁 「2025.07 베트남 보건복지부 인증 획득」
C9: 말레이시아 | D9: 의료기기청(MDA) | E9: =+인증현황!C81 | F9: =+인증현황!D79 | G9: =+인증현황!D80 | H9: 2025.11 인증 → 2026.01 공식 출시 | I9: 인증현황 No.31 + 연혁 「2025.12 MDA 인증」·「2026.01 공식 출시」
C10: 말레이시아 | D10: 의료기기청(MDA) | E10: =+인증현황!C87 | F10: =+인증현황!D85 | G10: =+인증현황!D86 | H10: 2026.04 인증 획득 (신제품 H10 첫 해외 인증) | I10: 인증현황 No.33 + 사업의 내용 「H10 말레이시아 인허가 완료」
C11: 베트남 | D11: 보건복지부(MOH) | E11: ANGEL SUIT H10 | F11: 2026.08.05 | G11: - | H11: Class B 의료기기 등록 완료 (H10 2번째 해외 등록) | I11: 언론 보도(2026.08.05). 반기보고서 기준일 이후 사건으로 공시 미반영
C12: 태국 | D12: TFDA | E12: ANGEL SUIT H10 | F12: - | G12: - | H12: 현지 대리점 계약 체결, 제품 등록·인허가 진행 중 | I12: 반기보고서 사업의 내용
C13: 인도네시아·싱가포르 | D13: 각국 규제기관 | E13: 엔젤렉스 M20 외 | F13: - | G13: - | H13: 인증 취득 범위 확대 예정 | I13: 반기보고서 사업의 내용
C14: 유럽 | D14: CE MDR | E14: 엔젤렉스 M20 외 | F14: - | G14: - | H14: 인증 지연 → 2024·2025년 수출 실적 미달 사유 | I14: 반기보고서 「예측치 대비 실적 비교」 괴리사유
C15: 미국 | D15: FDA | E15: angel GEAR (ANGEL X) | F15: 2022.12 | G15: - | H15: 등록 완료 | I15: 반기보고서 연혁 「2022.12 'ANGEL X' 美 FDA 등록」
C16: 미국 | D16: FDA | E16: angel SUIT / 의료기기 라인 | F16: - | G16: - | H16: 2026년 하반기 인증 준비 착수 예정 | I16: 반기보고서 사업의 내용
C17: 말레이시아 UiTM | D17: (임상 협력) | E17: 엔젤렉스 M20 2기 보급 | F17: 2022.05 | G17: - | H17: 전략적 협약(MOA) — 이후 다기관 RCT 참여기관 | I17: 반기보고서 연혁 + 연구개발활동
A18: 주1) 인증일·유효기간은 [인증현황] 시트 원문을 수식 참조하므로 원문 갱신 시 자동 반영됨
A19: 주2) 연혁 표는 말레이시아 M20을 2025.12로 기재하나 인증서 발급일은 2025.11.27 — 본 표는 인증서 발급일 기준
A20: 주3) 리딩투자증권(2025.12.16)은 태국·베트남 인허가를 '2023~2024년 획득'으로 서술하나 공시와 불일치. 공시 우선 적용
A23: x | B23: 인증 보유 현황 요약 (반기보고서 기준 34건)
C24: 구분 | D24: Unit | E24: MEDI | F24: SUIT | G24: GEAR | H24: KIT | I24: 시스템/기타 | J24: 합계
C25: 제품군별 인증 건수 | D25: 건 | E25: =COUNTIF(인증현황!$E$8:$E$89,"MEDI 제품군") | F25: =COUNTIF(인증현황!$E$8:$E$89,"SUIT 제품군") | G25: =COUNTIF(인증현황!$E$8:$E$89,"GEAR 제품군") | H25: =COUNTIF(인증현황!$E$8:$E$89,"KIT 제품군") | I25: =COUNTIF(인증현황!$E$8:$E$89,"-") | J25: =SUM(E25:I25)
C26: 구분 | D26: Unit | E26: 대한민국 | F26: 태국 | G26: 베트남 | H26: 말레이시아 | J26: 합계
C27: 출원국별 인증 건수 | D27: 건 | E27: =COUNTIF(인증현황!$F$8:$F$89,"대한민국") | F27: =COUNTIF(인증현황!$F$8:$F$89,"태국") | G27: =COUNTIF(인증현황!$F$8:$F$89,"베트남") | H27: =COUNTIF(인증현황!$F$8:$F$89,"말레이시아") | J27: =SUM(E27:H27)
A28: 주) [인증현황] 시트 원문을 COUNTIF로 집계. 반기보고서 기준일(2026.06.30) 이후 취득한 베트남 H10은 미포함
A31: x | B31: 수가 적용의 전제가 된 국내 인허가
C32: 구분 | D32: 인증 명칭 | E32: 대상 제품 | F32: 인증일 | G32: 유효기간 | H32: 의의
C33: 의료기기 3등급 | D33: =+인증현황!C18 | E33: =+인증현황!C19 | F33: =+인증현황!D17 | G33: =+인증현황!D18 | H33: 웨어러블 로봇 최초 3등급 품목허가 → MM304 선별급여 적용 개시의 전제
C34: 의료기기 2등급 | D34: =+인증현황!C15 | E34: =+인증현황!C16 | F34: =+인증현황!D14 | G34: =+인증현황!D15 | H34: MEDI 제품군 기본 등급
C35: 의료기기 2등급 | D35: =+인증현황!C66 | E35: =+인증현황!C67 | F35: =+인증현황!D65 | G35: =+인증현황!D66 | H35: angel SUIT H10 포함 SUIT 제품군
C36: 혁신제품 지정 | D36: =+인증현황!C23 | E36: =+인증현황!C24 | F36: =+인증현황!D23 | G36: =+인증현황!D24 | H36: 공공조달 수의계약 자격 — 2027.09 만료
C37: GMP | D37: =+인증현황!C8 | E37: =+인증현황!C9 | F37: =+인증현황!D8 | G37: =+인증현황!D9 | H37: 의료기기 제조·품질관리 기준
A38: ⚠ 의료기기 3등급 허가는 2027.12.13, 혁신제품 지정은 2027.09.23 만료 — 갱신 여부가 수가 매출의 전제조건
A41: x | B41: 기술 검증 이력
C42: 시기 | D42: 구분 | E42: 내용 | F42: 근거 (행별)
C43: 2018.02 | D43: 행사 | E43: 워크온슈트 평창 패럴림픽 성화봉송 행사지원 | F43: 반기보고서 연혁
C44: 2018 | D44: 수상 | E44: 올해의 대한민국 로봇기업 | F44: 한국IR협의회(2024.09.26) — 반기보고서 연혁 미기재 (2차)
C45: 2020.11 | D45: 수상 | E45: 국제 사이보그 올림픽(Cybathlon) 전동형 외골격 금메달·동메달 | F45: 반기보고서 연혁
C46: 2021.09 | D46: 선정 | E46: 공공조달수요발굴위원회 혁신제품 37개 선정 (한국판 뉴딜 시제품 지정트랙) | F46: 반기보고서 연혁 + 인증현황 No.7
C47: 2022.10 | D47: 선정 | E47: 국가연구개발 우수성과 100선 (기계소재 분야, 과학기술정보통신부) | F47: 반기보고서 연혁
C48: 2023.02 | D48: 선정 | E48: 산업통상자원부 기계·장비·로봇 분야 R&D 우수성과 | F48: 반기보고서 연혁
...

Sheet 인증현황
B2: 바. 주요 인증 내역
B4: 반기보고서 기준일 현재 당사의 사업과 관련한 제품 및 시스템에 대한 인허가 인증 내역은 다음과 같습니다.
B6: 번호 | C6: 내용 | D6: 인증일/ | E6: 적용 제품군 | F6: 출원국 | G6: 비고
D7: 인증기간
B8: 1 | C8: 의료기기 제조 및 품질관리 기준 적합인정서 | D8: 2025.06.26 | E8: - | F8: 대한민국 | G8: 시스템인증
C9: (GMP인정서) | D9: ~ 2028.06.25
B10: 2 | C10: ISO 13485:2016 | D10: 2025.08.30 | E10: - | F10: 대한민국 | G10: 시스템인증
C11: (의료기기 품질경영시스템) | D11: ~ 2028.08.29
B12: 3 | C12: ISO 9001:2015 | D12: 2025.08.23 | E12: - | F12: 대한민국 | G12: 시스템인증
C13: 재활의료기기(재활치료용 로봇 및 부품)의 설계, 개발 및 제조 | D13: ~ 2028.08.22
B14: 4 | C14: 의료기기 제조 인증서 | D14: 2021.03.02 | E14: MEDI 제품군 | F14: 대한민국 | G14: 제품인증
C15: 전동식 정형용 운동장치(2등급) | D15: ~ 2031.03.01
C16: ANGEL LEGS M20 (M20-A-C2 외 3건)
B17: 5 | C17: 의료기기 제조 허가증 | D17: 2022.12.14 | E17: MEDI 제품군 | F17: 대한민국 | G17: 제품인증
C18: 로봇보조 정형용 운동장치(3등급) | D18: ~ 2027.12.13
C19: ANGEL LEGS M20 (M20-A-C3 외 1건)
B20: 6 | C20: 의료기기 제조 신고증 | D20: 2022.02.18 | E20: MEDI 제품군 | F20: 대한민국 | G20: 제품인증
C21: 수동식 정형용 운동장치(1등급) | D21: ~ 2027.02.17
C22: 수동식탈부하보행훈련기 (MW10 외 1건)
B23: 7 | C23: 혁신제품 지정 인증서 | D23: 2021.09.24 | E23: MEDI 제품군 | F23: 대한민국 | G23: 제품인증
C24: (ANGEL LEGS M20-A, ANGEL LEGS M20-B) | D24: ~2027.09.23
B25: 8 | C25: 방송통신기자재등의 적합등록 (KC인증) | D25: 2020.08.27 | E25: MEDI 제품군 | F25: 대한민국 | G25: 제품인증
C26: CHARGING DOCK (M20 DOCK)
B27: 9 | C27: Declaration of Conformity (MD 2006/42/EC) | D27: 2023.04.03 | E27: GEAR 제품군 | F27: 대한민국 | G27: 제품인증
C28: Wearable robot for lower-back support (Angel X)
B29: 10 | C29: K마크 인증서(성능) | D29: 2023.08.01 | E29: GEAR 제품군 | F29: 대한민국 | G29: 제품인증
C30: 허리 하중 지지를 위한 작업자용 근력 보조기 | D30: ~2026.07.31
C31: (AX-L20-1BW 외 3건)
B32: 11 | C32: 방송통신기자재등의 적합등록 (KC인증) | D32: 2024.02.02 | E32: GEAR 제품군 | F32: 대한민국 | G32: 제품인증
C33: Motion Analyzer (AA-MA10)
B34: 12 | C34: 의료기기 제조 신고증 | D34: 2024.04.04 | E34: GEAR 제품군 | F34: 대한민국 | G34: 제품인증
C35: 팽창성 부목(1등급) | D35: ~2029.04.03
C36: angel GEAR soft W10 (AGS-W10-00LL 외 7건)
B37: 13 | C37: 의료기기 제조 신고증 | D37: 2024.04.04 | E37: GEAR 제품군 | F37: 대한민국 | G37: 제품인증
C38: 팽창성 부목(1등급) | D38: ~ 2029.04.03
C39: angel GEAR soft W11 (AGS-W11-00LL 외 7건)
B40: 14 | C40: 방송통신기자재등의 적합등록 (KC인증) | D40: 2019.02.01 | E40: SUIT 제품군 | F40: 대한민국 | G40: 제품인증
C41: 엔젤앵클
B42: 15 | C42: 방송통신기자재등의 적합등록 (KC인증) | D42: 2019.02.01 | E42: SUIT 제품군 | F42: 대한민국 | G42: 제품인증
C43: 엔젤조인트
...

Sheet 10_시장·산업
A2: 시장 규모 및 산업 구조
A5: x | B5: 글로벌 시장 규모
C6: 구분 | D6: Unit | E6: 2025 | F6: =+E6+1 | G6: … | H6: 2034 | I6: CAGR | O6: Source
C7: 외골격 웨어러블 로봇 | D7: USD bil | E7: 2.49 | F7: 3.52 | H7: 64.23 | I7: 0.437 | J7: '26~'34 | O7: https://www.fortunebusinessinsights.com/wearable-robotic-exoskeleton-market-104664
C9: 구분 | D9: Unit | E9: 2019 | F9: =+E9+1 | G9: =+F9+1 | H9: =+G9+1 | I9: =+H9+1 | J9: =+I9+1 | K9: =+J9+1 | L9: =+K9+1 | M9: CAGR | O9: https://zdnet.co.kr/view/?no=20231201163256
C10: 글로벌 로봇산업 | D10: USD bil | E10: =+E11+E12 | F10: =+F11+F12 | G10: =+G11+G12 | H10: =+H11+H12 | I10: =+I11+I12 | J10: =+J11+J12 | K10: =+K11+K12 | L10: =+L11+L12 | M10: =RATE(7,0,-E10,L10) | N10: '19~'26 | O10: 하나금융연구소, 로봇을 만나는 새로운 방법, 2023.03.10.
C11: 산업용 로봇 | D11: USD bil | E11: 13.8 | F11: 11.9 | G11: 13.7 | H11: 16.8 | I11: 18.9 | J11: 21.3 | K11: 23.9 | L11: 26.6 | M11: =RATE(7,0,-E11,L11) | N11: '19~'26
C12: 서비스용 로봇 | D12: USD bil | E12: 12.9 | F12: 15.9 | G12: 19.5 | H12: 22.2 | I12: 27 | J12: 32.7 | K12: 3.95 | L12: 47.5 | M12: =RATE(7,0,-E12,L12) | N12: '19~'26
A14: x | B14: 국내 로봇 산업 | O14: https://www.kiria.org/portal/policysut/portalPlcyReports.do
C15: 구분 | D15: Unit | E15: 2022 | F15: =+E15+1 | G15: =+F15+1 | H15: CAGR | O15: 한국로봇산업진흥원, 2024년 로봇산업 실태조사 결과보고서
C16: 매출 | D16: 억원 | E16: 58933 | F16: 59805 | G16: 61695 | H16: =RATE(2,0,-E16,G16) | I16: '22~'24
C17: 제조업용 로봇 | D17: 억원 | E17: 29747 | F17: 29903 | G17: 31075 | H17: =RATE(2,0,-E17,G17)
C18: 전문서비스용 로봇 | D18: 억원 | E18: 5417 | F18: 6143 | G18: 6424 | H18: =RATE(2,0,-E18,G18)
C19: 개인서비스용 로봇 | D19: 억원 | E19: 4406 | F19: 4313 | G19: 4386 | H19: =RATE(2,0,-E19,G19)
C20: 로봇부품 및 소프트웨어 | D20: 억원 | E20: 19363 | F20: 19446 | G20: 19810 | H20: =RATE(2,0,-E20,G20)
C21: 생산 | D21: 억원 | E21: 55265 | F21: 56912 | G21: 59447 | H21: =RATE(2,0,-E21,G21) | I21: '22~'24
C22: 제조업용 로봇 | D22: 억원 | E22: 27319 | F22: 27902 | G22: 29521 | H22: =RATE(2,0,-E22,G22)
C23: 전문서비스용 로봇 | D23: 억원 | E23: 5081 | F23: 5655 | G23: 6035 | H23: =RATE(2,0,-E23,G23)
C24: 개인서비스용 로봇 | D24: 억원 | E24: 4144 | F24: 4090 | G24: 4238 | H24: =RATE(2,0,-E24,G24)
C25: 로봇부품 및 소프트웨어 | D25: 억원 | E25: 18721 | F25: 19264 | G25: 19653 | H25: =RATE(2,0,-E25,G25)
C26: 수출 | D26: 억원 | E26: 12248 | F26: 12484 | G26: 12578 | H26: =RATE(2,0,-E26,G26) | I26: '22~'24
C27: 제조업용 로봇 | D27: 억원 | E27: 9327 | F27: 9248 | G27: 9297 | H27: =RATE(2,0,-E27,G27)
C28: 전문서비스용 로봇 | D28: 억원 | E28: 435 | F28: 713 | G28: 680 | H28: =RATE(2,0,-E28,G28)
C29: 개인서비스용 로봇 | D29: 억원 | E29: 688 | F29: 643 | G29: 648 | H29: =RATE(2,0,-E29,G29)
C30: 로봇부품 및 소프트웨어 | D30: 억원 | E30: 1798 | F30: 1880 | G30: 1953 | H30: =RATE(2,0,-E30,G30)
C31: 수입 | D31: 억원 | E31: 6380 | F31: 6562 | G31: 6895 | H31: =RATE(2,0,-E31,G31) | I31: '22~'24
C32: 제조업용 로봇 | D32: 억원 | E32: 4582 | F32: 4668 | G32: 4680 | H32: =RATE(2,0,-E32,G32)
C33: 전문서비스용 로봇 | D33: 억원 | E33: 270 | F33: 349 | G33: 331 | H33: =RATE(2,0,-E33,G33)
C34: 개인서비스용 로봇 | D34: 억원 | E34: 236 | F34: 189 | G34: 149 | H34: =RATE(2,0,-E34,G34)
C35: 로봇부품 및 소프트웨어 | D35: 억원 | E35: 1291 | F35: 1356 | G35: 1736 | H35: =RATE(2,0,-E35,G35)
A37: x | B37: 전문서비스용 로봇 출하 현황
C38: 구분 | D38: Unit | E38: 금액 | F38: 구성비
C39: 합계 | D39: 백만원 | E39: 615579 | F39: 1
C40: 사업시설 관리용 로봇 | D40: 백만원 | E40: 44144 | F40: 0.072
C41: 안전 및 극한작업용 로봇 | D41: 백만원 | E41: 89189 | F41: 0.145
C42: 의료용 로봇 | D42: 백만원 | E42: 116787 | F42: 0.19
C43: 건설용 로봇 | D43: 백만원 | E43: 26872 | F43: 0.044
C44: 군사용 로봇 | D44: 백만원 | E44: 36000 | F44: 0.058
C45: 농림어업용 로봇 | D45: 백만원 | E45: 59790 | F45: 0.097
C46: 여가 및 오락 서비스용 로봇 | D46: 백만원 | E46: 670 | F46: 0.001
...

Sheet 11_주가·밸류에이션
A2: 주가 추이 및 밸류에이션
B4: 2026년 상반기 월별 주가 및 거래실적
B5: 구분 | C5: 46023 | D5: 46054 | E5: 46082 | F5: 46113 | G5: 46143 | H5: 46174 | I5: 46204 | J5: 46235
B6: 월별 최고가(원) | C6: =IF(COUNTIFS(주가데이터!$A:$A,">="&EOMONTH(C$5,-1)+1,주가데이터!$A:$A,"<="&EOMONTH(C$5,0))=0,"-", _xlfn.MAXIFS(주가데이터!$B:$B,주가데이터!$A:$A,">="&EOMONTH(C$5,-1)+1,주가데이터!$A:$A,"<="&EOMONTH(C$5,0))) | D6: =IF(COUNTIFS(주가데이터!$A:$A,">="&EOMONTH(D$5,-1)+1,주가데이터!$A:$A,"<="&EOMONTH(D$5,0))=0,"-", _xlfn.MAXIFS(주가데이터!$B:$B,주가데이터!$A:$A,">="&EOMONTH(D$5,-1)+1,주가데이터!$A:$A,"<="&EOMONTH(D$5,0))) | E6: =IF(COUNTIFS(주가데이터!$A:$A,">="&EOMONTH(E$5,-1)+1,주가데이터!$A:$A,"<="&EOMONTH(E$5,0))=0,"-", _xlfn.MAXIFS(주가데이터!$B:$B,주가데이터!$A:$A,">="&EOMONTH(E$5,-1)+1,주가데이터!$A:$A,"<="&EOMONTH(E$5,0))) | F6: =IF(COUNTIFS(주가데이터!$A:$A,">="&EOMONTH(F$5,-1)+1,주가데이터!$A:$A,"<="&EOMONTH(F$5,0))=0,"-", _xlfn.MAXIFS(주가데이터!$B:$B,주가데이터!$A:$A,">="&EOMONTH(F$5,-1)+1,주가데이터!$A:$A,"<="&EOMONTH(F$5,0))) | G6: =IF(COUNTIFS(주가데이터!$A:$A,">="&EOMONTH(G$5,-1)+1,주가데이터!$A:$A,"<="&EOMONTH(G$5,0))=0,"-", _xlfn.MAXIFS(주가데이터!$B:$B,주가데이터!$A:$A,">="&EOMONTH(G$5,-1)+1,주가데이터!$A:$A,"<="&EOMONTH(G$5,0))) | H6: =IF(COUNTIFS(주가데이터!$A:$A,">="&EOMONTH(H$5,-1)+1,주가데이터!$A:$A,"<="&EOMONTH(H$5,0))=0,"-", _xlfn.MAXIFS(주가데이터!$B:$B,주가데이터!$A:$A,">="&EOMONTH(H$5,-1)+1,주가데이터!$A:$A,"<="&EOMONTH(H$5,0))) | I6: =IF(COUNTIFS(주가데이터!$A:$A,">="&EOMONTH(I$5,-1)+1,주가데이터!$A:$A,"<="&EOMONTH(I$5,0))=0,"-", _xlfn.MAXIFS(주가데이터!$B:$B,주가데이터!$A:$A,">="&EOMONTH(I$5,-1)+1,주가데이터!$A:$A,"<="&EOMONTH(I$5,0))) | J6: =IF(COUNTIFS(주가데이터!$A:$A,">="&EOMONTH(J$5,-1)+1,주가데이터!$A:$A,"<="&EOMONTH(J$5,0))=0,"-", _xlfn.MAXIFS(주가데이터!$B:$B,주가데이터!$A:$A,">="&EOMONTH(J$5,-1)+1,주가데이터!$A:$A,"<="&EOMONTH(J$5,0)))
B7: 월별 최저가(원) | C7: =IF(COUNTIFS(주가데이터!$A:$A,">="&EOMONTH(C$5,-1)+1,주가데이터!$A:$A,"<="&EOMONTH(C$5,0))=0,"-", _xlfn.MINIFS(주가데이터!$B:$B,주가데이터!$A:$A,">="&EOMONTH(C$5,-1)+1,주가데이터!$A:$A,"<="&EOMONTH(C$5,0))) | D7: =IF(COUNTIFS(주가데이터!$A:$A,">="&EOMONTH(D$5,-1)+1,주가데이터!$A:$A,"<="&EOMONTH(D$5,0))=0,"-", _xlfn.MINIFS(주가데이터!$B:$B,주가데이터!$A:$A,">="&EOMONTH(D$5,-1)+1,주가데이터!$A:$A,"<="&EOMONTH(D$5,0))) | E7: =IF(COUNTIFS(주가데이터!$A:$A,">="&EOMONTH(E$5,-1)+1,주가데이터!$A:$A,"<="&EOMONTH(E$5,0))=0,"-", _xlfn.MINIFS(주가데이터!$B:$B,주가데이터!$A:$A,">="&EOMONTH(E$5,-1)+1,주가데이터!$A:$A,"<="&EOMONTH(E$5,0))) | F7: =IF(COUNTIFS(주가데이터!$A:$A,">="&EOMONTH(F$5,-1)+1,주가데이터!$A:$A,"<="&EOMONTH(F$5,0))=0,"-", _xlfn.MINIFS(주가데이터!$B:$B,주가데이터!$A:$A,">="&EOMONTH(F$5,-1)+1,주가데이터!$A:$A,"<="&EOMONTH(F$5,0))) | G7: =IF(COUNTIFS(주가데이터!$A:$A,">="&EOMONTH(G$5,-1)+1,주가데이터!$A:$A,"<="&EOMONTH(G$5,0))=0,"-", _xlfn.MINIFS(주가데이터!$B:$B,주가데이터!$A:$A,">="&EOMONTH(G$5,-1)+1,주가데이터!$A:$A,"<="&EOMONTH(G$5,0))) | H7: =IF(COUNTIFS(주가데이터!$A:$A,">="&EOMONTH(H$5,-1)+1,주가데이터!$A:$A,"<="&EOMONTH(H$5,0))=0,"-", _xlfn.MINIFS(주가데이터!$B:$B,주가데이터!$A:$A,">="&EOMONTH(H$5,-1)+1,주가데이터!$A:$A,"<="&EOMONTH(H$5,0))) | I7: =IF(COUNTIFS(주가데이터!$A:$A,">="&EOMONTH(I$5,-1)+1,주가데이터!$A:$A,"<="&EOMONTH(I$5,0))=0,"-", _xlfn.MINIFS(주가데이터!$B:$B,주가데이터!$A:$A,">="&EOMONTH(I$5,-1)+1,주가데이터!$A:$A,"<="&EOMONTH(I$5,0))) | J7: =IF(COUNTIFS(주가데이터!$A:$A,">="&EOMONTH(J$5,-1)+1,주가데이터!$A:$A,"<="&EOMONTH(J$5,0))=0,"-", _xlfn.MINIFS(주가데이터!$B:$B,주가데이터!$A:$A,">="&EOMONTH(J$5,-1)+1,주가데이터!$A:$A,"<="&EOMONTH(J$5,0)))
B8: 평균주가(원) | C8: =IF(COUNTIFS(주가데이터!$A:$A,">="&EOMONTH(C$5,-1)+1,주가데이터!$A:$A,"<="&EOMONTH(C$5,0))=0,"-", ROUND(AVERAGEIFS(주가데이터!$B:$B,주가데이터!$A:$A,">="&EOMONTH(C$5,-1)+1,주가데이터!$A:$A,"<="&EOMONTH(C$5,0)),0)) | D8: =IF(COUNTIFS(주가데이터!$A:$A,">="&EOMONTH(D$5,-1)+1,주가데이터!$A:$A,"<="&EOMONTH(D$5,0))=0,"-", ROUND(AVERAGEIFS(주가데이터!$B:$B,주가데이터!$A:$A,">="&EOMONTH(D$5,-1)+1,주가데이터!$A:$A,"<="&EOMONTH(D$5,0)),0)) | E8: =IF(COUNTIFS(주가데이터!$A:$A,">="&EOMONTH(E$5,-1)+1,주가데이터!$A:$A,"<="&EOMONTH(E$5,0))=0,"-", ROUND(AVERAGEIFS(주가데이터!$B:$B,주가데이터!$A:$A,">="&EOMONTH(E$5,-1)+1,주가데이터!$A:$A,"<="&EOMONTH(E$5,0)),0)) | F8: =IF(COUNTIFS(주가데이터!$A:$A,">="&EOMONTH(F$5,-1)+1,주가데이터!$A:$A,"<="&EOMONTH(F$5,0))=0,"-", ROUND(AVERAGEIFS(주가데이터!$B:$B,주가데이터!$A:$A,">="&EOMONTH(F$5,-1)+1,주가데이터!$A:$A,"<="&EOMONTH(F$5,0)),0)) | G8: =IF(COUNTIFS(주가데이터!$A:$A,">="&EOMONTH(G$5,-1)+1,주가데이터!$A:$A,"<="&EOMONTH(G$5,0))=0,"-", ROUND(AVERAGEIFS(주가데이터!$B:$B,주가데이터!$A:$A,">="&EOMONTH(G$5,-1)+1,주가데이터!$A:$A,"<="&EOMONTH(G$5,0)),0)) | H8: =IF(COUNTIFS(주가데이터!$A:$A,">="&EOMONTH(H$5,-1)+1,주가데이터!$A:$A,"<="&EOMONTH(H$5,0))=0,"-", ROUND(AVERAGEIFS(주가데이터!$B:$B,주가데이터!$A:$A,">="&EOMONTH(H$5,-1)+1,주가데이터!$A:$A,"<="&EOMONTH(H$5,0)),0)) | I8: =IF(COUNTIFS(주가데이터!$A:$A,">="&EOMONTH(I$5,-1)+1,주가데이터!$A:$A,"<="&EOMONTH(I$5,0))=0,"-", ROUND(AVERAGEIFS(주가데이터!$B:$B,주가데이터!$A:$A,">="&EOMONTH(I$5,-1)+1,주가데이터!$A:$A,"<="&EOMONTH(I$5,0)),0)) | J8: =IF(COUNTIFS(주가데이터!$A:$A,">="&EOMONTH(J$5,-1)+1,주가데이터!$A:$A,"<="&EOMONTH(J$5,0))=0,"-", ROUND(AVERAGEIFS(주가데이터!$B:$B,주가데이터!$A:$A,">="&EOMONTH(J$5,-1)+1,주가데이터!$A:$A,"<="&EOMONTH(J$5,0)),0))
B9: 월간 거래량(주) | C9: =IF(COUNTIFS(주가데이터!$A:$A,">="&EOMONTH(C$5,-1)+1,주가데이터!$A:$A,"<="&EOMONTH(C$5,0))=0,"-", SUMIFS(주가데이터!$C:$C,주가데이터!$A:$A,">="&EOMONTH(C$5,-1)+1,주가데이터!$A:$A,"<="&EOMONTH(C$5,0))) | D9: =IF(COUNTIFS(주가데이터!$A:$A,">="&EOMONTH(D$5,-1)+1,주가데이터!$A:$A,"<="&EOMONTH(D$5,0))=0,"-", SUMIFS(주가데이터!$C:$C,주가데이터!$A:$A,">="&EOMONTH(D$5,-1)+1,주가데이터!$A:$A,"<="&EOMONTH(D$5,0))) | E9: =IF(COUNTIFS(주가데이터!$A:$A,">="&EOMONTH(E$5,-1)+1,주가데이터!$A:$A,"<="&EOMONTH(E$5,0))=0,"-", SUMIFS(주가데이터!$C:$C,주가데이터!$A:$A,">="&EOMONTH(E$5,-1)+1,주가데이터!$A:$A,"<="&EOMONTH(E$5,0))) | F9: =IF(COUNTIFS(주가데이터!$A:$A,">="&EOMONTH(F$5,-1)+1,주가데이터!$A:$A,"<="&EOMONTH(F$5,0))=0,"-", SUMIFS(주가데이터!$C:$C,주가데이터!$A:$A,">="&EOMONTH(F$5,-1)+1,주가데이터!$A:$A,"<="&EOMONTH(F$5,0))) | G9: =IF(COUNTIFS(주가데이터!$A:$A,">="&EOMONTH(G$5,-1)+1,주가데이터!$A:$A,"<="&EOMONTH(G$5,0))=0,"-", SUMIFS(주가데이터!$C:$C,주가데이터!$A:$A,">="&EOMONTH(G$5,-1)+1,주가데이터!$A:$A,"<="&EOMONTH(G$5,0))) | H9: =IF(COUNTIFS(주가데이터!$A:$A,">="&EOMONTH(H$5,-1)+1,주가데이터!$A:$A,"<="&EOMONTH(H$5,0))=0,"-", SUMIFS(주가데이터!$C:$C,주가데이터!$A:$A,">="&EOMONTH(H$5,-1)+1,주가데이터!$A:$A,"<="&EOMONTH(H$5,0))) | I9: =IF(COUNTIFS(주가데이터!$A:$A,">="&EOMONTH(I$5,-1)+1,주가데이터!$A:$A,"<="&EOMONTH(I$5,0))=0,"-", SUMIFS(주가데이터!$C:$C,주가데이터!$A:$A,">="&EOMONTH(I$5,-1)+1,주가데이터!$A:$A,"<="&EOMONTH(I$5,0))) | J9: =IF(COUNTIFS(주가데이터!$A:$A,">="&EOMONTH(J$5,-1)+1,주가데이터!$A:$A,"<="&EOMONTH(J$5,0))=0,"-", SUMIFS(주가데이터!$C:$C,주가데이터!$A:$A,">="&EOMONTH(J$5,-1)+1,주가데이터!$A:$A,"<="&EOMONTH(J$5,0)))
B11: 시가총액(백만원) | C11: =C8*15392981/1000000 | D11: =D8*15392981/1000000 | E11: =E8*15392981/1000000 | F11: =F8*15392981/1000000 | G11: =G8*15392981/1000000 | H11: =H8*15392981/1000000 | I11: =I8*15392981/1000000 | J11: =J8*15392981/1000000
B15: 장기 주가 추이
B16: 시점 | C16: 주가(원) | D16: 비고
B17: 2024.03.26 (상장일) | C17: 65000 | D17: 공모가 20,000원 / 시초가 50,500원
B18: 2024.09.23 | C18: 29850 | D18: 상장일 종가 대비 -54% / 한국IR협의회 기준일
B19: 2025.05.29 | C19: 23350 | D19: SK증권 리포트 기준일
B20: 2025.12.15 | C20: 32850 | D20: 리딩투자증권 기준일 / 시가총액 4,950억원
B21: 2026.06 평균 | C21: 23332 | D21: 6월 최저 18,230원 (공모가 하회)
B24: 상장 시 공모가 산정 내역
B25: 구분 | C25: 내용
B26: 비교기업 | C26: ㈜라온테크 PER 33.83배 / 삼익THK㈜ PER 40.90배 → 적용 PER 37.37배
B27: 적용 이익 | C27: 2026년 추정 당기순이익 11,450백만원
B28: 현가 환산 | C28: 연 할인율 15% 적용 → 2023년말 현가 7,529백만원
B29: 적용 주식수 | C29: 15,601,881주
B30: 주당 평가가액 | C30: 18,030원
B31: 희망공모가 밴드 | C31: 11,000 ~ 15,000원 (평가액 대비 16.81~38.99% 할인)
B32: 확정 공모가 | C32: 20,000원
A33: ⚠️ 공모가는 2026년 추정 당기순이익 11,450백만원을 전제로 산정되었으나, 2026년 반기 실적은 순손실 3,665백만원
B36: 동종 업종 밸류에이션 (2024.09.23 기준)
B37: 기업명 | C37: 종가(원) | D37: 시가총액(십억원) | E37: PSR(배, 2024F) | F37: PBR(배, 2024F)
B38: 엔젤로보틱스 | C38: 29850 | D38: 446 | E38: 66.1 | F38: 13.2
B39: 삼익THK | C39: 9820 | D39: 206 | E39: 0.6 | F39: 1
B40: 알에스오토메이션 | C40: 11560 | D40: 108 | E40: 1.2 | F40: 3
B41: 코스닥 평균 | C41: 755 | D41: 372025 | E41: 1.8 | F41: 2.4
A42: 출처: Quantiwise, 한국IR협의회 기업리서치센터 / 최근 3개월간 한국거래소 시장경보제도 지정 이력 없음

Sheet 주가데이터
A1: 일자 | B1: 종가 | C1: 거래량 | D1: 대비 | E1: 등락률 | F1: 시가 | G1: 고가 | H1: 저가 | I1: 거래대금 | J1: 시가총액 | K1: 상장주식수 | M1: 일자 | N1: (모두)
A2: 45377 | B2: 65000 | C2: 34678750 | D2: 45000 | E2: 225 | F2: 50500 | G2: 77700 | H2: 44100 | I2: 1956417590850 | J2: 910973440000 | K2: 14014976
A3: 45378 | B3: 66800 | C3: 13615567 | D3: 1800 | E3: 2.77 | F3: 71100 | G3: 76400 | H3: 65700 | I3: 980270773300 | J3: 936200396800 | K3: 14014976
A4: 45379 | B4: 61400 | C4: 4783790 | D4: -5400 | E4: -8.08 | F4: 64000 | G4: 66500 | H4: 57600 | I4: 292597717700 | J4: 860519526400 | K4: 14014976
A5: 45380 | B5: 68700 | C5: 14207848 | D5: 7300 | E5: 11.89 | F5: 60200 | G5: 74400 | H5: 59800 | I5: 995573499700 | J5: 962828851200 | K5: 14014976
A6: 45383 | B6: 66700 | C6: 2905786 | D6: -2000 | E6: -2.91 | F6: 69000 | G6: 69500 | H6: 64100 | I6: 194548920200 | J6: 934798899200 | K6: 14014976
A7: 45384 | B7: 60500 | C7: 1815163 | D7: -6200 | E7: -9.3 | F7: 65600 | G7: 66000 | H7: 60400 | I7: 113088437800 | J7: 847906048000 | K7: 14014976
A8: 45385 | B8: 59100 | C8: 3186838 | D8: -1400 | E8: -2.31 | F8: 58600 | G8: 65200 | H8: 56500 | I8: 194897647400 | J8: 828285081600 | K8: 14014976
A9: 45386 | B9: 59400 | C9: 1258767 | D9: 300 | E9: 0.51 | F9: 62500 | G9: 63300 | H9: 59300 | I9: 77152126200 | J9: 832489574400 | K9: 14014976
A10: 45387 | B10: 56500 | C10: 698739 | D10: -2900 | E10: -4.88 | F10: 57100 | G10: 59200 | H10: 56500 | I10: 39999055700 | J10: 791846144000 | K10: 14014976
A11: 45390 | B11: 53600 | C11: 728119 | D11: -2900 | E11: -5.13 | F11: 57500 | G11: 59300 | H11: 53500 | I11: 40753864300 | J11: 751202713600 | K11: 14014976
A12: 45391 | B12: 51200 | C12: 568187 | D12: -2400 | E12: -4.48 | F12: 53300 | G12: 54600 | H12: 50700 | I12: 29629349900 | J12: 717566771200 | K12: 14014976
A13: 45393 | B13: 50600 | C13: 454394 | D13: -600 | E13: -1.17 | F13: 50800 | G13: 52400 | H13: 49250 | I13: 23086434100 | J13: 709157785600 | K13: 14014976
... A588: 46259 | B588: 20850 | C588: 42302 | D588: 750 | E588: 3.73 | F588: 21200 | G588: 21200 | H588: 20000 | I588: 865729575 | J588: 320943653850 | K588: 15392981

Sheet 12_관리종목·시뮬레이션
A2: 관리종목 지정요건 및 자기자본 시뮬레이션
A3: 단위: 백만원 / 출처: 제10기 반기보고서 「관리종목 지정유예 현황」
B5: 요건별 유예 현황 (동사 공시 기준)
B6: 요건 | C6: 기준 | D6: 유예 종료 | E6: 적용 개시 | F6: 현황
B7: 매출액 | C7: 최근 사업연도 매출액 30억원 미만 | D7: 2028.12.31 | E7: 2029 사업연도 | F7: 2025년 4,641백만원 → 미해당
B8: 계속사업손실 | C8: 자기자본 50% 초과 세전손실이 최근 3년 중 2회 이상 및 최근 사업연도 손실 | D8: 2026.12.31 | E8: 2027 사업연도 | F8: 2025년 -29.8% → 미해당
B9: 자본잠식 | C9: 자본잠식률 50% 이상 또는 자기자본 10억원 미만 | D9: - | E9: - | F9: 자본금 7,696 / 자기자본 30,982 → 해당없음
B12: 세전손실 대비 자기자본 비율 (실적)
B13: 사업연도 | C13: 세전계속사업손익 (A) | D13: 자기자본 (B) | E13: 비율 (A/B) | F13: 요건 해당여부
B14: 2023년 | C14: -9239 | D14: 8678 | E14: =C14/D14 | F14: 미해당 (유예)
B15: 2024년 | C15: -10006 | D15: 40329 | E15: =C15/D15 | F15: 미해당
B16: 2025년 | C16: -9715 | D16: 32626 | E16: =C16/D16 | F16: 미해당
B19: 자기자본 및 판정비율 시뮬레이션
B20: 가정: 연간 세전손실 7,300백만원 (2026년 반기 실적 연간 환산) / 주식보상·옵션행사 유입 연 1,200백만원 / 2025년말 자기자본 32,626백만원 출발
C22: A안 : CPS 미발행 | E22: B안 : CPS 20,000백만원 발행
B23: 사업연도 | C23: 자기자본 | D23: 손실/자본 | E23: 자기자본 | F23: 손실/자본
B24: 2026년(E) | C24: =32626-$C$32+$C$33 | D24: =IF(C24<=0,"자본잠식",$C$32/C24) | E24: =32626+20000-$C$32+$C$33 | F24: =IF(E24<=0,"자본잠식",$C$32/E24)
B25: 2027년(E) | C25: =C24-$C$32+$C$33 | D25: =IF(C25<=0,"자본잠식",$C$32/C25) | E25: =E24-$C$32+$C$33 | F25: =IF(E25<=0,"자본잠식",$C$32/E25)
B26: 2028년(E) | C26: =C25-$C$32+$C$33 | D26: =IF(C26<=0,"자본잠식",$C$32/C26) | E26: =E25-$C$32+$C$33 | F26: =IF(E26<=0,"자본잠식",$C$32/E26)
B27: 2029년(E) | C27: =C26-$C$32+$C$33 | D27: =IF(C27<=0,"자본잠식",$C$32/C27) | E27: =E26-$C$32+$C$33 | F27: =IF(E27<=0,"자본잠식",$C$32/E27)
B28: 2030년(E) | C28: =C27-$C$32+$C$33 | D28: =IF(C28<=0,"자본잠식",$C$32/C28) | E28: =E27-$C$32+$C$33 | F28: =IF(E28<=0,"자본잠식",$C$32/E28)
B29: 2031년(E) | C29: =C28-$C$32+$C$33 | D29: =IF(C29<=0,"자본잠식",$C$32/C29) | E29: =E28-$C$32+$C$33 | F29: =IF(E29<=0,"자본잠식",$C$32/E29)
B32: 연간 세전손실 (가정) | C32: 7300
B33: 연간 자본 유입 (가정) | C33: 1200
A35: ※ 노란색 셀(C열 가정값)을 수정하면 시뮬레이션 전체가 재계산됨
A36: A안: 2028 사업연도에 판정비율이 50%를 초과하고 2029 사업연도 결산에서 최근 3년 중 2회가 성립하여 요건에 해당
A37: B안: 2031년까지 50%를 하회하여 투자자의 전환권 행사 가능 기간 전체를 커버
A38: ⚠️ 가정에 기초한 추정으로 실제 결과와 차이가 발생할 수 있으며, CPS의 자본 분류는 감사인 판단을 전제로 함
A39: 주) 실적표(위)의 비율은 공시 원문 표기를 따라 손실을 음수로 표시하였고, 시뮬레이션(아래)은 절대값 기준 양수로 표시함

Sheet 13_출처목록
A2: 자료 출처 목록
A3: 2026.08.26 기준
B5: 1차 자료 (공시)
B6: 자료명 | C6: 제출일 | D6: 성격 | E6: 활용 시트 | F6: 비고
B7: 제10기 반기보고서 | C7: 2026.08.14 | D7: 공시 원문 | E7: 01~04, 06~09, 11, 12 | F7: 최신·확정. 검토받은 반기재무제표
B8: 제9기 사업보고서 | C8: 2026.03.23 | D8: 공시 원문 | E8: 01, 03, 08 | F8: 감사의견 적정
B11: 2차 자료 (제3자 분석)
B12: 자료명 | C12: 작성일 | D12: 작성기관 | E12: 활용 시트 | F12: 비고
B13: 기업분석보고서 | C13: 2024.09.26 | D13: 한국IR협의회 기업리서치센터 | E13: 06, 09, 10, 11 | F13: 시장점유율·판매처·회수기간 도표 보유
B14: 기업분석 리포트 | C14: 2025.12.16 | D14: 리딩투자증권 | E14: 09, 10, 11 | F14: 가장 최신 증권사 리포트. Not Rated
B15: 기업분석 리포트 | C15: 2025.05.29 | D15: SK증권 | E15: 08, 10 | F15: 국가과제 리스트·엔젤라 플랫폼. Not Rated
B16: IPO 분석 리포트 | C16: 2024.03.06 | D16: 유진투자증권 | E16: 02, 10, 11 | F16: 침투율·공모가 산정·보호예수. 실적 전망은 outdated
B19: 웹 리서치 소스
B20: 항목 | C20: 기관/매체 | D20: 활용 시트 | E20: URL
B21: 국산 재활로봇 수가 미확보 이슈 | C21: 의학신문 | D21: 10 | E21: http://www.bosa.co.kr/news/articleView.html?idxno=2114946
B22: 로봇산업 실태조사 (국내 로봇산업 매출) | C22: 한국로봇산업진흥원 | D22: 10 | E22: https://www.kiria.org/portal/policysut/portalPlcyInquiry.do
B23: 로봇산업 실태조사 결과보고서 | C23: 공공데이터포털 | D23: 10 | E23: https://www.data.go.kr/data/3041731/fileData.do
B24: 고령인구 비율·장래인구추계 | C24: 국가데이터처 2025 고령자 통계 | D24: 10 | E24: https://www.kostat.go.kr/board.es?mid=a10301010000&bid=10820&list_no=438832
B25: 고령인구 100대 지표 | C25: KOSIS | D25: 10 | E25: https://kosis.kr/visual/nsportalStats/detailContents.do?listId=A&statJipyoId=3634
B26: 뇌졸중 환자수·재활 진료 통계 | C26: 건강보험심사평가원 의료빅데이터 | D26: 10 | E26: https://opendata.hira.or.kr/op/opc/selectMedInfoSvcList.do
B27: 재활로봇 보급사업·수가 체계 | C27: 국립재활원 재활연구소 | D27: 10 | E27: https://www.nrc.go.kr/research/html/content.do?depth=rp&menu_cd=03_04_00_01
B28: 외골격 웨어러블 로봇 시장 규모 | C28: Fortune Business Insights | D28: 10 | E28: https://www.fortunebusinessinsights.com/wearable-robotic-exoskeleton-market-104664
B29: 재활로봇 시장 규모 (대안 출처) | C29: GII Korea | D29: 10 | E29: https://www.giikorea.co.kr/report/gmi1858972-rehabilitation-robots-market-opportunity-growth.html
B30: 재활로봇 시장 규모 (대안 출처) | C30: Mordor Intelligence | D30: 10 | E30: https://www.mordorintelligence.kr/industry-reports/rehabilitation-robots-market
B31: 주가·거래 데이터 | C31: 한국거래소 정보데이터시스템 | D31: 11 | E31: http://data.krx.co.kr
... B38: 엔젤슈트 H10 베트남 의료기기 등록 (2026.08.05) | C38: ZDNet Korea / 로봇신문 | D38: 09 | E38: https://zdnet.co.kr/view/?no=20260805083950
A40: 주1) 웹 소스는 검색 결과 요약을 기반으로 하며, 본문 인용 시 원문 확인이 필요함
A41: 주2) DART·증권사·통계 사이트는 현재 작업 환경에서 직접 접속이 제한되어 1차 자료는 파일 업로드로 확보
B44: 미확보 항목 (발행사 확보 필요)
B45: 항목 | C45: 영향 범위 | D45: 우선순위
B46: 딜 조건 (규모·만기·금리·옵션) | C46: Term Sheet 전체 | D46: 높음
B47: CPS 자본분류 감사인 의견 | C47: 12_시뮬레이션 전제 | D47: 높음
B48: 아세안 수주 파이프라인 | C48: 해외 매출 논거 | D48: 높음
B49: BEP 매출 규모 | C49: 영업레버리지 논거 | D49: 높음
B50: 제품별 마진 | C50: 06_제품별매출 | D50: 중간
B51: 경쟁사 실명 및 최신 점유율 | C51: 10_시장·산업 | D51: 중간
B52: 침투율 최신화 (현재 2023년 기준) | C52: 10_시장·산업 | D52: 중간
B54: 추가 확인 필요 항목 (2026.08 리서치 결과)
B55: 항목 | C55: 영향 범위 | D55: 우선순위
B56: 신의료기술평가 '기존기술' 판정 근거 (NECA 공고) | C56: 10_수가체계 — 경쟁 차별화 논거 | D56: 높음
...
